{
 "cells": [
  {
   "cell_type": "code",
   "execution_count": 3,
   "id": "2d18ec00-5b09-4b5f-908d-a8c01be4e5ec",
   "metadata": {},
   "outputs": [],
   "source": [
    "my_list = list(range(10, 26))"
   ]
  },
  {
   "cell_type": "code",
   "execution_count": 2,
   "id": "6f46451c-f99d-46f4-a2cf-a3a6864eccc6",
   "metadata": {},
   "outputs": [
    {
     "name": "stdout",
     "output_type": "stream",
     "text": [
      "Contents of my_list: [10, 11, 12, 13, 14, 15, 16, 17, 18, 19, 20, 21, 22, 23, 24, 25]\n"
     ]
    }
   ],
   "source": [
    "print(\"Contents of my_list:\", my_list)"
   ]
  },
  {
   "cell_type": "code",
   "execution_count": 4,
   "id": "1cd6ffb5-e3e5-4dca-92a5-14e9d9c13248",
   "metadata": {},
   "outputs": [
    {
     "name": "stdout",
     "output_type": "stream",
     "text": [
      "Contents of my_list in reverse (using index slicing): [25, 24, 23, 22, 21, 20, 19, 18, 17, 16, 15, 14, 13, 12, 11, 10]\n"
     ]
    }
   ],
   "source": [
    "print(\"Contents of my_list in reverse (using index slicing):\", my_list[::-1])\n"
   ]
  },
  {
   "cell_type": "code",
   "execution_count": 9,
   "id": "8f03abf4-eccb-4892-9688-7c3eca80402c",
   "metadata": {},
   "outputs": [
    {
     "name": "stdout",
     "output_type": "stream",
     "text": [
      "25\n",
      "24\n",
      "23\n",
      "22\n",
      "21\n",
      "20\n",
      "19\n",
      "18\n",
      "17\n",
      "16\n",
      "15\n",
      "14\n",
      "13\n",
      "12\n",
      "11\n",
      "10\n"
     ]
    }
   ],
   "source": [
    "# print (\"Contents of my_list in reverse (using a loop):\") \n",
    "# for i in range(len(my_list)-1, -1, -1):\n",
    "#     print(my_list[i], end=\" \")\n",
    "\n",
    "for item in my_list[::-1]:\n",
    "    print (item)"
   ]
  },
  {
   "cell_type": "code",
   "execution_count": 7,
   "id": "b091e031-4f24-4f9c-bc0c-c4e804b3d545",
   "metadata": {},
   "outputs": [
    {
     "name": "stdout",
     "output_type": "stream",
     "text": [
      "Contents of my_list after append: [10, 11, 12, 13, 14, 15, 16, 17, 18, 19, 20, 21, 22, 23, 24, 25, [11, 19, 26]]\n",
      "Contents of my_list after extend: [10, 11, 12, 13, 14, 15, 16, 17, 18, 19, 20, 21, 22, 23, 24, 25, [11, 19, 26], 11, 19, 26]\n"
     ]
    }
   ],
   "source": [
    "my_list.append([11, 19, 26])\n",
    "print(\"Contents of my_list after append:\", my_list)\n",
    "\n",
    "my_list.extend([11, 19, 26])\n",
    "print(\"Contents of my_list after extend:\", my_list)\n"
   ]
  },
  {
   "cell_type": "code",
   "execution_count": 11,
   "id": "dfa0cddc-5947-4195-8782-84baa8c814aa",
   "metadata": {},
   "outputs": [
    {
     "name": "stdout",
     "output_type": "stream",
     "text": [
      "Contents of my_list after extending with 10 random integers: [10, 11, 12, 13, 14, 15, 16, 17, 18, 19, 20, 21, 22, 23, 24, 25, [11, 19, 26], 11, 19, 26, 52, 70, 1, 42, 97, 30, 22, 91, 25, 35]\n"
     ]
    }
   ],
   "source": [
    "import random\n",
    "\n",
    "random_integers = [random.randint(1, 100) for _ in range(10)]\n",
    "my_list.extend(random_integers)\n",
    "print(\"Contents of my_list after extending with 10 random integers:\", my_list)\n"
   ]
  },
  {
   "cell_type": "code",
   "execution_count": 12,
   "id": "14596409-a22a-4b3b-acdf-957b51df804a",
   "metadata": {},
   "outputs": [
    {
     "name": "stdout",
     "output_type": "stream",
     "text": [
      "Last value: 35\n",
      "Contents of my_list after removing last value: [10, 11, 12, 13, 14, 15, 16, 17, 18, 19, 20, 21, 22, 23, 24, 25, [11, 19, 26], 11, 19, 26, 52, 70, 1, 42, 97, 30, 22, 91, 25]\n"
     ]
    }
   ],
   "source": [
    "last_val = my_list[-1]\n",
    "my_list.pop()  \n",
    "print(\"Last value:\", last_val)\n",
    "print(\"Contents of my_list after removing last value:\", my_list)\n"
   ]
  },
  {
   "cell_type": "code",
   "execution_count": 13,
   "id": "53cbb2cf-faac-48a4-b494-b5647f14ecc0",
   "metadata": {},
   "outputs": [
    {
     "ename": "TypeError",
     "evalue": "unhashable type: 'list'",
     "output_type": "error",
     "traceback": [
      "\u001b[0;31m---------------------------------------------------------------------------\u001b[0m",
      "\u001b[0;31mTypeError\u001b[0m                                 Traceback (most recent call last)",
      "Cell \u001b[0;32mIn[13], line 1\u001b[0m\n\u001b[0;32m----> 1\u001b[0m my_set \u001b[38;5;241m=\u001b[39m \u001b[38;5;28mset\u001b[39m(my_list)\n\u001b[1;32m      2\u001b[0m \u001b[38;5;28mprint\u001b[39m(\u001b[38;5;124m\"\u001b[39m\u001b[38;5;124mmy_set:\u001b[39m\u001b[38;5;124m\"\u001b[39m, my_set)\n\u001b[1;32m      4\u001b[0m \u001b[38;5;66;03m# Try indexing\u001b[39;00m\n",
      "\u001b[0;31mTypeError\u001b[0m: unhashable type: 'list'"
     ]
    }
   ],
   "source": [
    "my_set = set(my_list)\n",
    "print(\"my_set:\", my_set)\n",
    "\n",
    "# Try indexing\n",
    "try:\n",
    "    second_element = my_set[1]\n",
    "except TypeError as e:\n",
    "    print(\"Error:\", e)\n"
   ]
  },
  {
   "cell_type": "code",
   "execution_count": 14,
   "id": "7bec73fc-1c76-4dee-803c-d7798f6097ac",
   "metadata": {},
   "outputs": [
    {
     "name": "stdout",
     "output_type": "stream",
     "text": [
      "my_tuple: (10, 11, 12, 13, 14, 15, 16, 17, 18, 19, 20, 21, 22, 23, 24, 25, [11, 19, 26], 11, 19, 26, 52, 70, 1, 42, 97, 30, 22, 91, 25)\n",
      "Error: 'tuple' object does not support item assignment\n"
     ]
    }
   ],
   "source": [
    "my_tuple = tuple(my_list)\n",
    "print(\"my_tuple:\", my_tuple)\n",
    "\n",
    "# Try assigning a value to the fourth element\n",
    "try:\n",
    "    my_tuple[3] = 5\n",
    "except TypeError as e:\n",
    "    print(\"Error:\", e)\n"
   ]
  },
  {
   "cell_type": "code",
   "execution_count": 18,
   "id": "54fef507-108a-4847-89f2-be4803093c2f",
   "metadata": {},
   "outputs": [],
   "source": [
    "my_dict = {}\n"
   ]
  },
  {
   "cell_type": "code",
   "execution_count": 21,
   "id": "097ba82f-5ffb-4757-bb52-b63bdc533b96",
   "metadata": {},
   "outputs": [
    {
     "name": "stdout",
     "output_type": "stream",
     "text": [
      "Channels:\n",
      " - defaults\n",
      "Platform: osx-64\n",
      "Collecting package metadata (repodata.json): done\n",
      "Solving environment: done\n",
      "\n",
      "## Package Plan ##\n",
      "\n",
      "  environment location: /opt/anaconda3\n",
      "\n",
      "  added / updated specs:\n",
      "    - inflect\n",
      "\n",
      "\n",
      "The following NEW packages will be INSTALLED:\n",
      "\n",
      "  inflect            pkgs/main/osx-64::inflect-7.0.0-py312hecd8cb5_0 \n",
      "\n",
      "The following packages will be UPDATED:\n",
      "\n",
      "  ca-certificates                      2024.3.11-hecd8cb5_0 --> 2024.7.2-hecd8cb5_0 \n",
      "  certifi                          2024.6.2-py312hecd8cb5_0 --> 2024.8.30-py312hecd8cb5_0 \n",
      "  conda                              24.5.0-py312hecd8cb5_0 --> 24.7.1-py312hecd8cb5_0 \n",
      "  openssl                                 3.0.14-h46256e1_0 --> 3.0.15-h46256e1_0 \n",
      "\n",
      "\n",
      "\n",
      "Downloading and Extracting Packages:\n",
      "\n",
      "Preparing transaction: done\n",
      "Verifying transaction: failed\n",
      "\n",
      "CondaVerificationError: The package for conda located at /opt/anaconda3/pkgs/conda-24.7.1-py312hecd8cb5_0\n",
      "appears to be corrupted. The path 'bin/activate'\n",
      "specified in the package manifest cannot be found.\n",
      "\n",
      "CondaVerificationError: The package for conda located at /opt/anaconda3/pkgs/conda-24.7.1-py312hecd8cb5_0\n",
      "appears to be corrupted. The path 'bin/conda'\n",
      "specified in the package manifest cannot be found.\n",
      "\n",
      "CondaVerificationError: The package for conda located at /opt/anaconda3/pkgs/conda-24.7.1-py312hecd8cb5_0\n",
      "appears to be corrupted. The path 'bin/conda-env'\n",
      "specified in the package manifest cannot be found.\n",
      "\n",
      "CondaVerificationError: The package for conda located at /opt/anaconda3/pkgs/conda-24.7.1-py312hecd8cb5_0\n",
      "appears to be corrupted. The path 'bin/deactivate'\n",
      "specified in the package manifest cannot be found.\n",
      "\n",
      "CondaVerificationError: The package for conda located at /opt/anaconda3/pkgs/conda-24.7.1-py312hecd8cb5_0\n",
      "appears to be corrupted. The path 'condabin/conda'\n",
      "specified in the package manifest cannot be found.\n",
      "\n",
      "CondaVerificationError: The package for conda located at /opt/anaconda3/pkgs/conda-24.7.1-py312hecd8cb5_0\n",
      "appears to be corrupted. The path 'etc/fish/conf.d/conda.fish'\n",
      "specified in the package manifest cannot be found.\n",
      "\n",
      "CondaVerificationError: The package for conda located at /opt/anaconda3/pkgs/conda-24.7.1-py312hecd8cb5_0\n",
      "appears to be corrupted. The path 'etc/profile.d/conda.csh'\n",
      "specified in the package manifest cannot be found.\n",
      "\n",
      "CondaVerificationError: The package for conda located at /opt/anaconda3/pkgs/conda-24.7.1-py312hecd8cb5_0\n",
      "appears to be corrupted. The path 'etc/profile.d/conda.sh'\n",
      "specified in the package manifest cannot be found.\n",
      "\n",
      "CondaVerificationError: The package for conda located at /opt/anaconda3/pkgs/conda-24.7.1-py312hecd8cb5_0\n",
      "appears to be corrupted. The path 'lib/python3.12/site-packages/conda-24.7.1.dist-info/INSTALLER'\n",
      "specified in the package manifest cannot be found.\n",
      "\n",
      "CondaVerificationError: The package for conda located at /opt/anaconda3/pkgs/conda-24.7.1-py312hecd8cb5_0\n",
      "appears to be corrupted. The path 'lib/python3.12/site-packages/conda-24.7.1.dist-info/METADATA'\n",
      "specified in the package manifest cannot be found.\n",
      "\n",
      "CondaVerificationError: The package for conda located at /opt/anaconda3/pkgs/conda-24.7.1-py312hecd8cb5_0\n",
      "appears to be corrupted. The path 'lib/python3.12/site-packages/conda-24.7.1.dist-info/RECORD'\n",
      "specified in the package manifest cannot be found.\n",
      "\n",
      "CondaVerificationError: The package for conda located at /opt/anaconda3/pkgs/conda-24.7.1-py312hecd8cb5_0\n",
      "appears to be corrupted. The path 'lib/python3.12/site-packages/conda-24.7.1.dist-info/REQUESTED'\n",
      "specified in the package manifest cannot be found.\n",
      "\n",
      "CondaVerificationError: The package for conda located at /opt/anaconda3/pkgs/conda-24.7.1-py312hecd8cb5_0\n",
      "appears to be corrupted. The path 'lib/python3.12/site-packages/conda-24.7.1.dist-info/WHEEL'\n",
      "specified in the package manifest cannot be found.\n",
      "\n",
      "CondaVerificationError: The package for conda located at /opt/anaconda3/pkgs/conda-24.7.1-py312hecd8cb5_0\n",
      "appears to be corrupted. The path 'lib/python3.12/site-packages/conda-24.7.1.dist-info/direct_url.json'\n",
      "specified in the package manifest cannot be found.\n",
      "\n",
      "CondaVerificationError: The package for conda located at /opt/anaconda3/pkgs/conda-24.7.1-py312hecd8cb5_0\n",
      "appears to be corrupted. The path 'lib/python3.12/site-packages/conda-24.7.1.dist-info/entry_points.txt'\n",
      "specified in the package manifest cannot be found.\n",
      "\n",
      "CondaVerificationError: The package for conda located at /opt/anaconda3/pkgs/conda-24.7.1-py312hecd8cb5_0\n",
      "appears to be corrupted. The path 'lib/python3.12/site-packages/conda-24.7.1.dist-info/licenses/AUTHORS.md'\n",
      "specified in the package manifest cannot be found.\n",
      "\n",
      "CondaVerificationError: The package for conda located at /opt/anaconda3/pkgs/conda-24.7.1-py312hecd8cb5_0\n",
      "appears to be corrupted. The path 'lib/python3.12/site-packages/conda-24.7.1.dist-info/licenses/LICENSE'\n",
      "specified in the package manifest cannot be found.\n",
      "\n",
      "CondaVerificationError: The package for conda located at /opt/anaconda3/pkgs/conda-24.7.1-py312hecd8cb5_0\n",
      "appears to be corrupted. The path 'lib/python3.12/site-packages/conda/__init__.py'\n",
      "specified in the package manifest cannot be found.\n",
      "\n",
      "CondaVerificationError: The package for conda located at /opt/anaconda3/pkgs/conda-24.7.1-py312hecd8cb5_0\n",
      "appears to be corrupted. The path 'lib/python3.12/site-packages/conda/__main__.py'\n",
      "specified in the package manifest cannot be found.\n",
      "\n",
      "CondaVerificationError: The package for conda located at /opt/anaconda3/pkgs/conda-24.7.1-py312hecd8cb5_0\n",
      "appears to be corrupted. The path 'lib/python3.12/site-packages/conda/__pycache__/__init__.cpython-312.pyc'\n",
      "specified in the package manifest cannot be found.\n",
      "\n",
      "CondaVerificationError: The package for conda located at /opt/anaconda3/pkgs/conda-24.7.1-py312hecd8cb5_0\n",
      "appears to be corrupted. The path 'lib/python3.12/site-packages/conda/__pycache__/activate.cpython-312.pyc'\n",
      "specified in the package manifest cannot be found.\n",
      "\n",
      "CondaVerificationError: The package for conda located at /opt/anaconda3/pkgs/conda-24.7.1-py312hecd8cb5_0\n",
      "appears to be corrupted. The path 'lib/python3.12/site-packages/conda/__pycache__/api.cpython-312.pyc'\n",
      "specified in the package manifest cannot be found.\n",
      "\n",
      "CondaVerificationError: The package for conda located at /opt/anaconda3/pkgs/conda-24.7.1-py312hecd8cb5_0\n",
      "appears to be corrupted. The path 'lib/python3.12/site-packages/conda/__pycache__/deprecations.cpython-312.pyc'\n",
      "specified in the package manifest cannot be found.\n",
      "\n",
      "CondaVerificationError: The package for conda located at /opt/anaconda3/pkgs/conda-24.7.1-py312hecd8cb5_0\n",
      "appears to be corrupted. The path 'lib/python3.12/site-packages/conda/__pycache__/exception_handler.cpython-312.pyc'\n",
      "specified in the package manifest cannot be found.\n",
      "\n",
      "CondaVerificationError: The package for conda located at /opt/anaconda3/pkgs/conda-24.7.1-py312hecd8cb5_0\n",
      "appears to be corrupted. The path 'lib/python3.12/site-packages/conda/__pycache__/exceptions.cpython-312.pyc'\n",
      "specified in the package manifest cannot be found.\n",
      "\n",
      "CondaVerificationError: The package for conda located at /opt/anaconda3/pkgs/conda-24.7.1-py312hecd8cb5_0\n",
      "appears to be corrupted. The path 'lib/python3.12/site-packages/conda/__pycache__/exports.cpython-312.pyc'\n",
      "specified in the package manifest cannot be found.\n",
      "\n",
      "CondaVerificationError: The package for conda located at /opt/anaconda3/pkgs/conda-24.7.1-py312hecd8cb5_0\n",
      "appears to be corrupted. The path 'lib/python3.12/site-packages/conda/__pycache__/history.cpython-312.pyc'\n",
      "specified in the package manifest cannot be found.\n",
      "\n",
      "CondaVerificationError: The package for conda located at /opt/anaconda3/pkgs/conda-24.7.1-py312hecd8cb5_0\n",
      "appears to be corrupted. The path 'lib/python3.12/site-packages/conda/__pycache__/misc.cpython-312.pyc'\n",
      "specified in the package manifest cannot be found.\n",
      "\n",
      "CondaVerificationError: The package for conda located at /opt/anaconda3/pkgs/conda-24.7.1-py312hecd8cb5_0\n",
      "appears to be corrupted. The path 'lib/python3.12/site-packages/conda/__pycache__/plan.cpython-312.pyc'\n",
      "specified in the package manifest cannot be found.\n",
      "\n",
      "CondaVerificationError: The package for conda located at /opt/anaconda3/pkgs/conda-24.7.1-py312hecd8cb5_0\n",
      "appears to be corrupted. The path 'lib/python3.12/site-packages/conda/__pycache__/resolve.cpython-312.pyc'\n",
      "specified in the package manifest cannot be found.\n",
      "\n",
      "CondaVerificationError: The package for conda located at /opt/anaconda3/pkgs/conda-24.7.1-py312hecd8cb5_0\n",
      "appears to be corrupted. The path 'lib/python3.12/site-packages/conda/__pycache__/utils.cpython-312.pyc'\n",
      "specified in the package manifest cannot be found.\n",
      "\n",
      "CondaVerificationError: The package for conda located at /opt/anaconda3/pkgs/conda-24.7.1-py312hecd8cb5_0\n",
      "appears to be corrupted. The path 'lib/python3.12/site-packages/conda/_vendor/__init__.py'\n",
      "specified in the package manifest cannot be found.\n",
      "\n",
      "CondaVerificationError: The package for conda located at /opt/anaconda3/pkgs/conda-24.7.1-py312hecd8cb5_0\n",
      "appears to be corrupted. The path 'lib/python3.12/site-packages/conda/_vendor/__pycache__/appdirs.cpython-312.pyc'\n",
      "specified in the package manifest cannot be found.\n",
      "\n",
      "CondaVerificationError: The package for conda located at /opt/anaconda3/pkgs/conda-24.7.1-py312hecd8cb5_0\n",
      "appears to be corrupted. The path 'lib/python3.12/site-packages/conda/_vendor/__pycache__/distro.cpython-312.pyc'\n",
      "specified in the package manifest cannot be found.\n",
      "\n",
      "CondaVerificationError: The package for conda located at /opt/anaconda3/pkgs/conda-24.7.1-py312hecd8cb5_0\n",
      "appears to be corrupted. The path 'lib/python3.12/site-packages/conda/_vendor/appdirs.LICENSE.txt'\n",
      "specified in the package manifest cannot be found.\n",
      "\n",
      "CondaVerificationError: The package for conda located at /opt/anaconda3/pkgs/conda-24.7.1-py312hecd8cb5_0\n",
      "appears to be corrupted. The path 'lib/python3.12/site-packages/conda/_vendor/appdirs.py'\n",
      "specified in the package manifest cannot be found.\n",
      "\n",
      "CondaVerificationError: The package for conda located at /opt/anaconda3/pkgs/conda-24.7.1-py312hecd8cb5_0\n",
      "appears to be corrupted. The path 'lib/python3.12/site-packages/conda/_vendor/cpuinfo/__init__.py'\n",
      "specified in the package manifest cannot be found.\n",
      "\n",
      "CondaVerificationError: The package for conda located at /opt/anaconda3/pkgs/conda-24.7.1-py312hecd8cb5_0\n",
      "appears to be corrupted. The path 'lib/python3.12/site-packages/conda/_vendor/cpuinfo/__pycache__/cpuinfo.cpython-312.pyc'\n",
      "specified in the package manifest cannot be found.\n",
      "\n",
      "CondaVerificationError: The package for conda located at /opt/anaconda3/pkgs/conda-24.7.1-py312hecd8cb5_0\n",
      "appears to be corrupted. The path 'lib/python3.12/site-packages/conda/_vendor/cpuinfo/cpuinfo.py'\n",
      "specified in the package manifest cannot be found.\n",
      "\n",
      "CondaVerificationError: The package for conda located at /opt/anaconda3/pkgs/conda-24.7.1-py312hecd8cb5_0\n",
      "appears to be corrupted. The path 'lib/python3.12/site-packages/conda/_vendor/distro.LICENSE.txt'\n",
      "specified in the package manifest cannot be found.\n",
      "\n",
      "CondaVerificationError: The package for conda located at /opt/anaconda3/pkgs/conda-24.7.1-py312hecd8cb5_0\n",
      "appears to be corrupted. The path 'lib/python3.12/site-packages/conda/_vendor/distro.py'\n",
      "specified in the package manifest cannot be found.\n",
      "\n",
      "CondaVerificationError: The package for conda located at /opt/anaconda3/pkgs/conda-24.7.1-py312hecd8cb5_0\n",
      "appears to be corrupted. The path 'lib/python3.12/site-packages/conda/_vendor/frozendict/LICENSE.txt'\n",
      "specified in the package manifest cannot be found.\n",
      "\n",
      "CondaVerificationError: The package for conda located at /opt/anaconda3/pkgs/conda-24.7.1-py312hecd8cb5_0\n",
      "appears to be corrupted. The path 'lib/python3.12/site-packages/conda/_vendor/frozendict/__init__.py'\n",
      "specified in the package manifest cannot be found.\n",
      "\n",
      "CondaVerificationError: The package for conda located at /opt/anaconda3/pkgs/conda-24.7.1-py312hecd8cb5_0\n",
      "appears to be corrupted. The path 'lib/python3.12/site-packages/conda/_vendor/frozendict/__pycache__/__init__.cpython-312.pyc'\n",
      "specified in the package manifest cannot be found.\n",
      "\n",
      "CondaVerificationError: The package for conda located at /opt/anaconda3/pkgs/conda-24.7.1-py312hecd8cb5_0\n",
      "appears to be corrupted. The path 'lib/python3.12/site-packages/conda/_vendor/py_cpuinfo.LICENSE'\n",
      "specified in the package manifest cannot be found.\n",
      "\n",
      "CondaVerificationError: The package for conda located at /opt/anaconda3/pkgs/conda-24.7.1-py312hecd8cb5_0\n",
      "appears to be corrupted. The path 'lib/python3.12/site-packages/conda/_vendor/vendor.txt'\n",
      "specified in the package manifest cannot be found.\n",
      "\n",
      "CondaVerificationError: The package for conda located at /opt/anaconda3/pkgs/conda-24.7.1-py312hecd8cb5_0\n",
      "appears to be corrupted. The path 'lib/python3.12/site-packages/conda/_version.py'\n",
      "specified in the package manifest cannot be found.\n",
      "\n",
      "CondaVerificationError: The package for conda located at /opt/anaconda3/pkgs/conda-24.7.1-py312hecd8cb5_0\n",
      "appears to be corrupted. The path 'lib/python3.12/site-packages/conda/activate.py'\n",
      "specified in the package manifest cannot be found.\n",
      "\n",
      "CondaVerificationError: The package for conda located at /opt/anaconda3/pkgs/conda-24.7.1-py312hecd8cb5_0\n",
      "appears to be corrupted. The path 'lib/python3.12/site-packages/conda/api.py'\n",
      "specified in the package manifest cannot be found.\n",
      "\n",
      "CondaVerificationError: The package for conda located at /opt/anaconda3/pkgs/conda-24.7.1-py312hecd8cb5_0\n",
      "appears to be corrupted. The path 'lib/python3.12/site-packages/conda/auxlib/LICENSE'\n",
      "specified in the package manifest cannot be found.\n",
      "\n",
      "CondaVerificationError: The package for conda located at /opt/anaconda3/pkgs/conda-24.7.1-py312hecd8cb5_0\n",
      "appears to be corrupted. The path 'lib/python3.12/site-packages/conda/auxlib/__init__.py'\n",
      "specified in the package manifest cannot be found.\n",
      "\n",
      "CondaVerificationError: The package for conda located at /opt/anaconda3/pkgs/conda-24.7.1-py312hecd8cb5_0\n",
      "appears to be corrupted. The path 'lib/python3.12/site-packages/conda/auxlib/__pycache__/__init__.cpython-312.pyc'\n",
      "specified in the package manifest cannot be found.\n",
      "\n",
      "CondaVerificationError: The package for conda located at /opt/anaconda3/pkgs/conda-24.7.1-py312hecd8cb5_0\n",
      "appears to be corrupted. The path 'lib/python3.12/site-packages/conda/auxlib/__pycache__/collection.cpython-312.pyc'\n",
      "specified in the package manifest cannot be found.\n",
      "\n",
      "CondaVerificationError: The package for conda located at /opt/anaconda3/pkgs/conda-24.7.1-py312hecd8cb5_0\n",
      "appears to be corrupted. The path 'lib/python3.12/site-packages/conda/auxlib/__pycache__/decorators.cpython-312.pyc'\n",
      "specified in the package manifest cannot be found.\n",
      "\n",
      "CondaVerificationError: The package for conda located at /opt/anaconda3/pkgs/conda-24.7.1-py312hecd8cb5_0\n",
      "appears to be corrupted. The path 'lib/python3.12/site-packages/conda/auxlib/__pycache__/entity.cpython-312.pyc'\n",
      "specified in the package manifest cannot be found.\n",
      "\n",
      "CondaVerificationError: The package for conda located at /opt/anaconda3/pkgs/conda-24.7.1-py312hecd8cb5_0\n",
      "appears to be corrupted. The path 'lib/python3.12/site-packages/conda/auxlib/__pycache__/logz.cpython-312.pyc'\n",
      "specified in the package manifest cannot be found.\n",
      "\n",
      "CondaVerificationError: The package for conda located at /opt/anaconda3/pkgs/conda-24.7.1-py312hecd8cb5_0\n",
      "appears to be corrupted. The path 'lib/python3.12/site-packages/conda/auxlib/__pycache__/type_coercion.cpython-312.pyc'\n",
      "specified in the package manifest cannot be found.\n",
      "\n",
      "CondaVerificationError: The package for conda located at /opt/anaconda3/pkgs/conda-24.7.1-py312hecd8cb5_0\n",
      "appears to be corrupted. The path 'lib/python3.12/site-packages/conda/auxlib/collection.py'\n",
      "specified in the package manifest cannot be found.\n",
      "\n",
      "CondaVerificationError: The package for conda located at /opt/anaconda3/pkgs/conda-24.7.1-py312hecd8cb5_0\n",
      "appears to be corrupted. The path 'lib/python3.12/site-packages/conda/auxlib/compat.py'\n",
      "specified in the package manifest cannot be found.\n",
      "\n",
      "CondaVerificationError: The package for conda located at /opt/anaconda3/pkgs/conda-24.7.1-py312hecd8cb5_0\n",
      "appears to be corrupted. The path 'lib/python3.12/site-packages/conda/auxlib/decorators.py'\n",
      "specified in the package manifest cannot be found.\n",
      "\n",
      "CondaVerificationError: The package for conda located at /opt/anaconda3/pkgs/conda-24.7.1-py312hecd8cb5_0\n",
      "appears to be corrupted. The path 'lib/python3.12/site-packages/conda/auxlib/entity.py'\n",
      "specified in the package manifest cannot be found.\n",
      "\n",
      "CondaVerificationError: The package for conda located at /opt/anaconda3/pkgs/conda-24.7.1-py312hecd8cb5_0\n",
      "appears to be corrupted. The path 'lib/python3.12/site-packages/conda/auxlib/exceptions.py'\n",
      "specified in the package manifest cannot be found.\n",
      "\n",
      "CondaVerificationError: The package for conda located at /opt/anaconda3/pkgs/conda-24.7.1-py312hecd8cb5_0\n",
      "appears to be corrupted. The path 'lib/python3.12/site-packages/conda/auxlib/ish.py'\n",
      "specified in the package manifest cannot be found.\n",
      "\n",
      "CondaVerificationError: The package for conda located at /opt/anaconda3/pkgs/conda-24.7.1-py312hecd8cb5_0\n",
      "appears to be corrupted. The path 'lib/python3.12/site-packages/conda/auxlib/logz.py'\n",
      "specified in the package manifest cannot be found.\n",
      "\n",
      "CondaVerificationError: The package for conda located at /opt/anaconda3/pkgs/conda-24.7.1-py312hecd8cb5_0\n",
      "appears to be corrupted. The path 'lib/python3.12/site-packages/conda/auxlib/type_coercion.py'\n",
      "specified in the package manifest cannot be found.\n",
      "\n",
      "CondaVerificationError: The package for conda located at /opt/anaconda3/pkgs/conda-24.7.1-py312hecd8cb5_0\n",
      "appears to be corrupted. The path 'lib/python3.12/site-packages/conda/base/__init__.py'\n",
      "specified in the package manifest cannot be found.\n",
      "\n",
      "CondaVerificationError: The package for conda located at /opt/anaconda3/pkgs/conda-24.7.1-py312hecd8cb5_0\n",
      "appears to be corrupted. The path 'lib/python3.12/site-packages/conda/base/__pycache__/constants.cpython-312.pyc'\n",
      "specified in the package manifest cannot be found.\n",
      "\n",
      "CondaVerificationError: The package for conda located at /opt/anaconda3/pkgs/conda-24.7.1-py312hecd8cb5_0\n",
      "appears to be corrupted. The path 'lib/python3.12/site-packages/conda/base/__pycache__/context.cpython-312.pyc'\n",
      "specified in the package manifest cannot be found.\n",
      "\n",
      "CondaVerificationError: The package for conda located at /opt/anaconda3/pkgs/conda-24.7.1-py312hecd8cb5_0\n",
      "appears to be corrupted. The path 'lib/python3.12/site-packages/conda/base/constants.py'\n",
      "specified in the package manifest cannot be found.\n",
      "\n",
      "CondaVerificationError: The package for conda located at /opt/anaconda3/pkgs/conda-24.7.1-py312hecd8cb5_0\n",
      "appears to be corrupted. The path 'lib/python3.12/site-packages/conda/base/context.py'\n",
      "specified in the package manifest cannot be found.\n",
      "\n",
      "CondaVerificationError: The package for conda located at /opt/anaconda3/pkgs/conda-24.7.1-py312hecd8cb5_0\n",
      "appears to be corrupted. The path 'lib/python3.12/site-packages/conda/base/exceptions.py'\n",
      "specified in the package manifest cannot be found.\n",
      "\n",
      "CondaVerificationError: The package for conda located at /opt/anaconda3/pkgs/conda-24.7.1-py312hecd8cb5_0\n",
      "appears to be corrupted. The path 'lib/python3.12/site-packages/conda/cli/__init__.py'\n",
      "specified in the package manifest cannot be found.\n",
      "\n",
      "CondaVerificationError: The package for conda located at /opt/anaconda3/pkgs/conda-24.7.1-py312hecd8cb5_0\n",
      "appears to be corrupted. The path 'lib/python3.12/site-packages/conda/cli/__pycache__/common.cpython-312.pyc'\n",
      "specified in the package manifest cannot be found.\n",
      "\n",
      "CondaVerificationError: The package for conda located at /opt/anaconda3/pkgs/conda-24.7.1-py312hecd8cb5_0\n",
      "appears to be corrupted. The path 'lib/python3.12/site-packages/conda/cli/__pycache__/conda_argparse.cpython-312.pyc'\n",
      "specified in the package manifest cannot be found.\n",
      "\n",
      "CondaVerificationError: The package for conda located at /opt/anaconda3/pkgs/conda-24.7.1-py312hecd8cb5_0\n",
      "appears to be corrupted. The path 'lib/python3.12/site-packages/conda/cli/__pycache__/find_commands.cpython-312.pyc'\n",
      "specified in the package manifest cannot be found.\n",
      "\n",
      "CondaVerificationError: The package for conda located at /opt/anaconda3/pkgs/conda-24.7.1-py312hecd8cb5_0\n",
      "appears to be corrupted. The path 'lib/python3.12/site-packages/conda/cli/__pycache__/helpers.cpython-312.pyc'\n",
      "specified in the package manifest cannot be found.\n",
      "\n",
      "CondaVerificationError: The package for conda located at /opt/anaconda3/pkgs/conda-24.7.1-py312hecd8cb5_0\n",
      "appears to be corrupted. The path 'lib/python3.12/site-packages/conda/cli/__pycache__/install.cpython-312.pyc'\n",
      "specified in the package manifest cannot be found.\n",
      "\n",
      "CondaVerificationError: The package for conda located at /opt/anaconda3/pkgs/conda-24.7.1-py312hecd8cb5_0\n",
      "appears to be corrupted. The path 'lib/python3.12/site-packages/conda/cli/__pycache__/main.cpython-312.pyc'\n",
      "specified in the package manifest cannot be found.\n",
      "\n",
      "CondaVerificationError: The package for conda located at /opt/anaconda3/pkgs/conda-24.7.1-py312hecd8cb5_0\n",
      "appears to be corrupted. The path 'lib/python3.12/site-packages/conda/cli/__pycache__/main_clean.cpython-312.pyc'\n",
      "specified in the package manifest cannot be found.\n",
      "\n",
      "CondaVerificationError: The package for conda located at /opt/anaconda3/pkgs/conda-24.7.1-py312hecd8cb5_0\n",
      "appears to be corrupted. The path 'lib/python3.12/site-packages/conda/cli/__pycache__/main_compare.cpython-312.pyc'\n",
      "specified in the package manifest cannot be found.\n",
      "\n",
      "CondaVerificationError: The package for conda located at /opt/anaconda3/pkgs/conda-24.7.1-py312hecd8cb5_0\n",
      "appears to be corrupted. The path 'lib/python3.12/site-packages/conda/cli/__pycache__/main_config.cpython-312.pyc'\n",
      "specified in the package manifest cannot be found.\n",
      "\n",
      "CondaVerificationError: The package for conda located at /opt/anaconda3/pkgs/conda-24.7.1-py312hecd8cb5_0\n",
      "appears to be corrupted. The path 'lib/python3.12/site-packages/conda/cli/__pycache__/main_create.cpython-312.pyc'\n",
      "specified in the package manifest cannot be found.\n",
      "\n",
      "CondaVerificationError: The package for conda located at /opt/anaconda3/pkgs/conda-24.7.1-py312hecd8cb5_0\n",
      "appears to be corrupted. The path 'lib/python3.12/site-packages/conda/cli/__pycache__/main_env_create.cpython-312.pyc'\n",
      "specified in the package manifest cannot be found.\n",
      "\n",
      "CondaVerificationError: The package for conda located at /opt/anaconda3/pkgs/conda-24.7.1-py312hecd8cb5_0\n",
      "appears to be corrupted. The path 'lib/python3.12/site-packages/conda/cli/__pycache__/main_env_update.cpython-312.pyc'\n",
      "specified in the package manifest cannot be found.\n",
      "\n",
      "CondaVerificationError: The package for conda located at /opt/anaconda3/pkgs/conda-24.7.1-py312hecd8cb5_0\n",
      "appears to be corrupted. The path 'lib/python3.12/site-packages/conda/cli/__pycache__/main_env_vars.cpython-312.pyc'\n",
      "specified in the package manifest cannot be found.\n",
      "\n",
      "CondaVerificationError: The package for conda located at /opt/anaconda3/pkgs/conda-24.7.1-py312hecd8cb5_0\n",
      "appears to be corrupted. The path 'lib/python3.12/site-packages/conda/cli/__pycache__/main_export.cpython-312.pyc'\n",
      "specified in the package manifest cannot be found.\n",
      "\n",
      "CondaVerificationError: The package for conda located at /opt/anaconda3/pkgs/conda-24.7.1-py312hecd8cb5_0\n",
      "appears to be corrupted. The path 'lib/python3.12/site-packages/conda/cli/__pycache__/main_info.cpython-312.pyc'\n",
      "specified in the package manifest cannot be found.\n",
      "\n",
      "CondaVerificationError: The package for conda located at /opt/anaconda3/pkgs/conda-24.7.1-py312hecd8cb5_0\n",
      "appears to be corrupted. The path 'lib/python3.12/site-packages/conda/cli/__pycache__/main_init.cpython-312.pyc'\n",
      "specified in the package manifest cannot be found.\n",
      "\n",
      "CondaVerificationError: The package for conda located at /opt/anaconda3/pkgs/conda-24.7.1-py312hecd8cb5_0\n",
      "appears to be corrupted. The path 'lib/python3.12/site-packages/conda/cli/__pycache__/main_install.cpython-312.pyc'\n",
      "specified in the package manifest cannot be found.\n",
      "\n",
      "CondaVerificationError: The package for conda located at /opt/anaconda3/pkgs/conda-24.7.1-py312hecd8cb5_0\n",
      "appears to be corrupted. The path 'lib/python3.12/site-packages/conda/cli/__pycache__/main_list.cpython-312.pyc'\n",
      "specified in the package manifest cannot be found.\n",
      "\n",
      "CondaVerificationError: The package for conda located at /opt/anaconda3/pkgs/conda-24.7.1-py312hecd8cb5_0\n",
      "appears to be corrupted. The path 'lib/python3.12/site-packages/conda/cli/__pycache__/main_package.cpython-312.pyc'\n",
      "specified in the package manifest cannot be found.\n",
      "\n",
      "CondaVerificationError: The package for conda located at /opt/anaconda3/pkgs/conda-24.7.1-py312hecd8cb5_0\n",
      "appears to be corrupted. The path 'lib/python3.12/site-packages/conda/cli/__pycache__/main_remove.cpython-312.pyc'\n",
      "specified in the package manifest cannot be found.\n",
      "\n",
      "CondaVerificationError: The package for conda located at /opt/anaconda3/pkgs/conda-24.7.1-py312hecd8cb5_0\n",
      "appears to be corrupted. The path 'lib/python3.12/site-packages/conda/cli/__pycache__/main_rename.cpython-312.pyc'\n",
      "specified in the package manifest cannot be found.\n",
      "\n",
      "CondaVerificationError: The package for conda located at /opt/anaconda3/pkgs/conda-24.7.1-py312hecd8cb5_0\n",
      "appears to be corrupted. The path 'lib/python3.12/site-packages/conda/cli/__pycache__/main_run.cpython-312.pyc'\n",
      "specified in the package manifest cannot be found.\n",
      "\n",
      "CondaVerificationError: The package for conda located at /opt/anaconda3/pkgs/conda-24.7.1-py312hecd8cb5_0\n",
      "appears to be corrupted. The path 'lib/python3.12/site-packages/conda/cli/__pycache__/main_search.cpython-312.pyc'\n",
      "specified in the package manifest cannot be found.\n",
      "\n",
      "CondaVerificationError: The package for conda located at /opt/anaconda3/pkgs/conda-24.7.1-py312hecd8cb5_0\n",
      "appears to be corrupted. The path 'lib/python3.12/site-packages/conda/cli/__pycache__/python_api.cpython-312.pyc'\n",
      "specified in the package manifest cannot be found.\n",
      "\n",
      "CondaVerificationError: The package for conda located at /opt/anaconda3/pkgs/conda-24.7.1-py312hecd8cb5_0\n",
      "appears to be corrupted. The path 'lib/python3.12/site-packages/conda/cli/actions.py'\n",
      "specified in the package manifest cannot be found.\n",
      "\n",
      "CondaVerificationError: The package for conda located at /opt/anaconda3/pkgs/conda-24.7.1-py312hecd8cb5_0\n",
      "appears to be corrupted. The path 'lib/python3.12/site-packages/conda/cli/common.py'\n",
      "specified in the package manifest cannot be found.\n",
      "\n",
      "CondaVerificationError: The package for conda located at /opt/anaconda3/pkgs/conda-24.7.1-py312hecd8cb5_0\n",
      "appears to be corrupted. The path 'lib/python3.12/site-packages/conda/cli/conda_argparse.py'\n",
      "specified in the package manifest cannot be found.\n",
      "\n",
      "CondaVerificationError: The package for conda located at /opt/anaconda3/pkgs/conda-24.7.1-py312hecd8cb5_0\n",
      "appears to be corrupted. The path 'lib/python3.12/site-packages/conda/cli/find_commands.py'\n",
      "specified in the package manifest cannot be found.\n",
      "\n",
      "CondaVerificationError: The package for conda located at /opt/anaconda3/pkgs/conda-24.7.1-py312hecd8cb5_0\n",
      "appears to be corrupted. The path 'lib/python3.12/site-packages/conda/cli/helpers.py'\n",
      "specified in the package manifest cannot be found.\n",
      "\n",
      "CondaVerificationError: The package for conda located at /opt/anaconda3/pkgs/conda-24.7.1-py312hecd8cb5_0\n",
      "appears to be corrupted. The path 'lib/python3.12/site-packages/conda/cli/install.py'\n",
      "specified in the package manifest cannot be found.\n",
      "\n",
      "CondaVerificationError: The package for conda located at /opt/anaconda3/pkgs/conda-24.7.1-py312hecd8cb5_0\n",
      "appears to be corrupted. The path 'lib/python3.12/site-packages/conda/cli/main.py'\n",
      "specified in the package manifest cannot be found.\n",
      "\n",
      "CondaVerificationError: The package for conda located at /opt/anaconda3/pkgs/conda-24.7.1-py312hecd8cb5_0\n",
      "appears to be corrupted. The path 'lib/python3.12/site-packages/conda/cli/main_clean.py'\n",
      "specified in the package manifest cannot be found.\n",
      "\n",
      "CondaVerificationError: The package for conda located at /opt/anaconda3/pkgs/conda-24.7.1-py312hecd8cb5_0\n",
      "appears to be corrupted. The path 'lib/python3.12/site-packages/conda/cli/main_compare.py'\n",
      "specified in the package manifest cannot be found.\n",
      "\n",
      "CondaVerificationError: The package for conda located at /opt/anaconda3/pkgs/conda-24.7.1-py312hecd8cb5_0\n",
      "appears to be corrupted. The path 'lib/python3.12/site-packages/conda/cli/main_config.py'\n",
      "specified in the package manifest cannot be found.\n",
      "\n",
      "CondaVerificationError: The package for conda located at /opt/anaconda3/pkgs/conda-24.7.1-py312hecd8cb5_0\n",
      "appears to be corrupted. The path 'lib/python3.12/site-packages/conda/cli/main_create.py'\n",
      "specified in the package manifest cannot be found.\n",
      "\n",
      "CondaVerificationError: The package for conda located at /opt/anaconda3/pkgs/conda-24.7.1-py312hecd8cb5_0\n",
      "appears to be corrupted. The path 'lib/python3.12/site-packages/conda/cli/main_env.py'\n",
      "specified in the package manifest cannot be found.\n",
      "\n",
      "CondaVerificationError: The package for conda located at /opt/anaconda3/pkgs/conda-24.7.1-py312hecd8cb5_0\n",
      "appears to be corrupted. The path 'lib/python3.12/site-packages/conda/cli/main_env_config.py'\n",
      "specified in the package manifest cannot be found.\n",
      "\n",
      "CondaVerificationError: The package for conda located at /opt/anaconda3/pkgs/conda-24.7.1-py312hecd8cb5_0\n",
      "appears to be corrupted. The path 'lib/python3.12/site-packages/conda/cli/main_env_create.py'\n",
      "specified in the package manifest cannot be found.\n",
      "\n",
      "CondaVerificationError: The package for conda located at /opt/anaconda3/pkgs/conda-24.7.1-py312hecd8cb5_0\n",
      "appears to be corrupted. The path 'lib/python3.12/site-packages/conda/cli/main_env_export.py'\n",
      "specified in the package manifest cannot be found.\n",
      "\n",
      "CondaVerificationError: The package for conda located at /opt/anaconda3/pkgs/conda-24.7.1-py312hecd8cb5_0\n",
      "appears to be corrupted. The path 'lib/python3.12/site-packages/conda/cli/main_env_list.py'\n",
      "specified in the package manifest cannot be found.\n",
      "\n",
      "CondaVerificationError: The package for conda located at /opt/anaconda3/pkgs/conda-24.7.1-py312hecd8cb5_0\n",
      "appears to be corrupted. The path 'lib/python3.12/site-packages/conda/cli/main_env_remove.py'\n",
      "specified in the package manifest cannot be found.\n",
      "\n",
      "CondaVerificationError: The package for conda located at /opt/anaconda3/pkgs/conda-24.7.1-py312hecd8cb5_0\n",
      "appears to be corrupted. The path 'lib/python3.12/site-packages/conda/cli/main_env_update.py'\n",
      "specified in the package manifest cannot be found.\n",
      "\n",
      "CondaVerificationError: The package for conda located at /opt/anaconda3/pkgs/conda-24.7.1-py312hecd8cb5_0\n",
      "appears to be corrupted. The path 'lib/python3.12/site-packages/conda/cli/main_env_vars.py'\n",
      "specified in the package manifest cannot be found.\n",
      "\n",
      "CondaVerificationError: The package for conda located at /opt/anaconda3/pkgs/conda-24.7.1-py312hecd8cb5_0\n",
      "appears to be corrupted. The path 'lib/python3.12/site-packages/conda/cli/main_export.py'\n",
      "specified in the package manifest cannot be found.\n",
      "\n",
      "CondaVerificationError: The package for conda located at /opt/anaconda3/pkgs/conda-24.7.1-py312hecd8cb5_0\n",
      "appears to be corrupted. The path 'lib/python3.12/site-packages/conda/cli/main_info.py'\n",
      "specified in the package manifest cannot be found.\n",
      "\n",
      "CondaVerificationError: The package for conda located at /opt/anaconda3/pkgs/conda-24.7.1-py312hecd8cb5_0\n",
      "appears to be corrupted. The path 'lib/python3.12/site-packages/conda/cli/main_init.py'\n",
      "specified in the package manifest cannot be found.\n",
      "\n",
      "CondaVerificationError: The package for conda located at /opt/anaconda3/pkgs/conda-24.7.1-py312hecd8cb5_0\n",
      "appears to be corrupted. The path 'lib/python3.12/site-packages/conda/cli/main_install.py'\n",
      "specified in the package manifest cannot be found.\n",
      "\n",
      "CondaVerificationError: The package for conda located at /opt/anaconda3/pkgs/conda-24.7.1-py312hecd8cb5_0\n",
      "appears to be corrupted. The path 'lib/python3.12/site-packages/conda/cli/main_list.py'\n",
      "specified in the package manifest cannot be found.\n",
      "\n",
      "CondaVerificationError: The package for conda located at /opt/anaconda3/pkgs/conda-24.7.1-py312hecd8cb5_0\n",
      "appears to be corrupted. The path 'lib/python3.12/site-packages/conda/cli/main_mock_activate.py'\n",
      "specified in the package manifest cannot be found.\n",
      "\n",
      "CondaVerificationError: The package for conda located at /opt/anaconda3/pkgs/conda-24.7.1-py312hecd8cb5_0\n",
      "appears to be corrupted. The path 'lib/python3.12/site-packages/conda/cli/main_mock_deactivate.py'\n",
      "specified in the package manifest cannot be found.\n",
      "\n",
      "CondaVerificationError: The package for conda located at /opt/anaconda3/pkgs/conda-24.7.1-py312hecd8cb5_0\n",
      "appears to be corrupted. The path 'lib/python3.12/site-packages/conda/cli/main_notices.py'\n",
      "specified in the package manifest cannot be found.\n",
      "\n",
      "CondaVerificationError: The package for conda located at /opt/anaconda3/pkgs/conda-24.7.1-py312hecd8cb5_0\n",
      "appears to be corrupted. The path 'lib/python3.12/site-packages/conda/cli/main_package.py'\n",
      "specified in the package manifest cannot be found.\n",
      "\n",
      "CondaVerificationError: The package for conda located at /opt/anaconda3/pkgs/conda-24.7.1-py312hecd8cb5_0\n",
      "appears to be corrupted. The path 'lib/python3.12/site-packages/conda/cli/main_pip.py'\n",
      "specified in the package manifest cannot be found.\n",
      "\n",
      "CondaVerificationError: The package for conda located at /opt/anaconda3/pkgs/conda-24.7.1-py312hecd8cb5_0\n",
      "appears to be corrupted. The path 'lib/python3.12/site-packages/conda/cli/main_remove.py'\n",
      "specified in the package manifest cannot be found.\n",
      "\n",
      "CondaVerificationError: The package for conda located at /opt/anaconda3/pkgs/conda-24.7.1-py312hecd8cb5_0\n",
      "appears to be corrupted. The path 'lib/python3.12/site-packages/conda/cli/main_rename.py'\n",
      "specified in the package manifest cannot be found.\n",
      "\n",
      "CondaVerificationError: The package for conda located at /opt/anaconda3/pkgs/conda-24.7.1-py312hecd8cb5_0\n",
      "appears to be corrupted. The path 'lib/python3.12/site-packages/conda/cli/main_run.py'\n",
      "specified in the package manifest cannot be found.\n",
      "\n",
      "CondaVerificationError: The package for conda located at /opt/anaconda3/pkgs/conda-24.7.1-py312hecd8cb5_0\n",
      "appears to be corrupted. The path 'lib/python3.12/site-packages/conda/cli/main_search.py'\n",
      "specified in the package manifest cannot be found.\n",
      "\n",
      "CondaVerificationError: The package for conda located at /opt/anaconda3/pkgs/conda-24.7.1-py312hecd8cb5_0\n",
      "appears to be corrupted. The path 'lib/python3.12/site-packages/conda/cli/main_update.py'\n",
      "specified in the package manifest cannot be found.\n",
      "\n",
      "CondaVerificationError: The package for conda located at /opt/anaconda3/pkgs/conda-24.7.1-py312hecd8cb5_0\n",
      "appears to be corrupted. The path 'lib/python3.12/site-packages/conda/cli/python_api.py'\n",
      "specified in the package manifest cannot be found.\n",
      "\n",
      "CondaVerificationError: The package for conda located at /opt/anaconda3/pkgs/conda-24.7.1-py312hecd8cb5_0\n",
      "appears to be corrupted. The path 'lib/python3.12/site-packages/conda/common/__init__.py'\n",
      "specified in the package manifest cannot be found.\n",
      "\n",
      "CondaVerificationError: The package for conda located at /opt/anaconda3/pkgs/conda-24.7.1-py312hecd8cb5_0\n",
      "appears to be corrupted. The path 'lib/python3.12/site-packages/conda/common/__pycache__/_logic.cpython-312.pyc'\n",
      "specified in the package manifest cannot be found.\n",
      "\n",
      "CondaVerificationError: The package for conda located at /opt/anaconda3/pkgs/conda-24.7.1-py312hecd8cb5_0\n",
      "appears to be corrupted. The path 'lib/python3.12/site-packages/conda/common/__pycache__/compat.cpython-312.pyc'\n",
      "specified in the package manifest cannot be found.\n",
      "\n",
      "CondaVerificationError: The package for conda located at /opt/anaconda3/pkgs/conda-24.7.1-py312hecd8cb5_0\n",
      "appears to be corrupted. The path 'lib/python3.12/site-packages/conda/common/__pycache__/configuration.cpython-312.pyc'\n",
      "specified in the package manifest cannot be found.\n",
      "\n",
      "CondaVerificationError: The package for conda located at /opt/anaconda3/pkgs/conda-24.7.1-py312hecd8cb5_0\n",
      "appears to be corrupted. The path 'lib/python3.12/site-packages/conda/common/__pycache__/io.cpython-312.pyc'\n",
      "specified in the package manifest cannot be found.\n",
      "\n",
      "CondaVerificationError: The package for conda located at /opt/anaconda3/pkgs/conda-24.7.1-py312hecd8cb5_0\n",
      "appears to be corrupted. The path 'lib/python3.12/site-packages/conda/common/__pycache__/logic.cpython-312.pyc'\n",
      "specified in the package manifest cannot be found.\n",
      "\n",
      "CondaVerificationError: The package for conda located at /opt/anaconda3/pkgs/conda-24.7.1-py312hecd8cb5_0\n",
      "appears to be corrupted. The path 'lib/python3.12/site-packages/conda/common/__pycache__/path.cpython-312.pyc'\n",
      "specified in the package manifest cannot be found.\n",
      "\n",
      "CondaVerificationError: The package for conda located at /opt/anaconda3/pkgs/conda-24.7.1-py312hecd8cb5_0\n",
      "appears to be corrupted. The path 'lib/python3.12/site-packages/conda/common/__pycache__/toposort.cpython-312.pyc'\n",
      "specified in the package manifest cannot be found.\n",
      "\n",
      "CondaVerificationError: The package for conda located at /opt/anaconda3/pkgs/conda-24.7.1-py312hecd8cb5_0\n",
      "appears to be corrupted. The path 'lib/python3.12/site-packages/conda/common/__pycache__/url.cpython-312.pyc'\n",
      "specified in the package manifest cannot be found.\n",
      "\n",
      "CondaVerificationError: The package for conda located at /opt/anaconda3/pkgs/conda-24.7.1-py312hecd8cb5_0\n",
      "appears to be corrupted. The path 'lib/python3.12/site-packages/conda/common/_logic.py'\n",
      "specified in the package manifest cannot be found.\n",
      "\n",
      "CondaVerificationError: The package for conda located at /opt/anaconda3/pkgs/conda-24.7.1-py312hecd8cb5_0\n",
      "appears to be corrupted. The path 'lib/python3.12/site-packages/conda/common/_os/__init__.py'\n",
      "specified in the package manifest cannot be found.\n",
      "\n",
      "CondaVerificationError: The package for conda located at /opt/anaconda3/pkgs/conda-24.7.1-py312hecd8cb5_0\n",
      "appears to be corrupted. The path 'lib/python3.12/site-packages/conda/common/_os/__pycache__/windows.cpython-312.pyc'\n",
      "specified in the package manifest cannot be found.\n",
      "\n",
      "CondaVerificationError: The package for conda located at /opt/anaconda3/pkgs/conda-24.7.1-py312hecd8cb5_0\n",
      "appears to be corrupted. The path 'lib/python3.12/site-packages/conda/common/_os/linux.py'\n",
      "specified in the package manifest cannot be found.\n",
      "\n",
      "CondaVerificationError: The package for conda located at /opt/anaconda3/pkgs/conda-24.7.1-py312hecd8cb5_0\n",
      "appears to be corrupted. The path 'lib/python3.12/site-packages/conda/common/_os/unix.py'\n",
      "specified in the package manifest cannot be found.\n",
      "\n",
      "CondaVerificationError: The package for conda located at /opt/anaconda3/pkgs/conda-24.7.1-py312hecd8cb5_0\n",
      "appears to be corrupted. The path 'lib/python3.12/site-packages/conda/common/_os/windows.py'\n",
      "specified in the package manifest cannot be found.\n",
      "\n",
      "CondaVerificationError: The package for conda located at /opt/anaconda3/pkgs/conda-24.7.1-py312hecd8cb5_0\n",
      "appears to be corrupted. The path 'lib/python3.12/site-packages/conda/common/compat.py'\n",
      "specified in the package manifest cannot be found.\n",
      "\n",
      "CondaVerificationError: The package for conda located at /opt/anaconda3/pkgs/conda-24.7.1-py312hecd8cb5_0\n",
      "appears to be corrupted. The path 'lib/python3.12/site-packages/conda/common/configuration.py'\n",
      "specified in the package manifest cannot be found.\n",
      "\n",
      "CondaVerificationError: The package for conda located at /opt/anaconda3/pkgs/conda-24.7.1-py312hecd8cb5_0\n",
      "appears to be corrupted. The path 'lib/python3.12/site-packages/conda/common/constants.py'\n",
      "specified in the package manifest cannot be found.\n",
      "\n",
      "CondaVerificationError: The package for conda located at /opt/anaconda3/pkgs/conda-24.7.1-py312hecd8cb5_0\n",
      "appears to be corrupted. The path 'lib/python3.12/site-packages/conda/common/decorators.py'\n",
      "specified in the package manifest cannot be found.\n",
      "\n",
      "CondaVerificationError: The package for conda located at /opt/anaconda3/pkgs/conda-24.7.1-py312hecd8cb5_0\n",
      "appears to be corrupted. The path 'lib/python3.12/site-packages/conda/common/disk.py'\n",
      "specified in the package manifest cannot be found.\n",
      "\n",
      "CondaVerificationError: The package for conda located at /opt/anaconda3/pkgs/conda-24.7.1-py312hecd8cb5_0\n",
      "appears to be corrupted. The path 'lib/python3.12/site-packages/conda/common/io.py'\n",
      "specified in the package manifest cannot be found.\n",
      "\n",
      "CondaVerificationError: The package for conda located at /opt/anaconda3/pkgs/conda-24.7.1-py312hecd8cb5_0\n",
      "appears to be corrupted. The path 'lib/python3.12/site-packages/conda/common/iterators.py'\n",
      "specified in the package manifest cannot be found.\n",
      "\n",
      "CondaVerificationError: The package for conda located at /opt/anaconda3/pkgs/conda-24.7.1-py312hecd8cb5_0\n",
      "appears to be corrupted. The path 'lib/python3.12/site-packages/conda/common/logic.py'\n",
      "specified in the package manifest cannot be found.\n",
      "\n",
      "CondaVerificationError: The package for conda located at /opt/anaconda3/pkgs/conda-24.7.1-py312hecd8cb5_0\n",
      "appears to be corrupted. The path 'lib/python3.12/site-packages/conda/common/path.py'\n",
      "specified in the package manifest cannot be found.\n",
      "\n",
      "CondaVerificationError: The package for conda located at /opt/anaconda3/pkgs/conda-24.7.1-py312hecd8cb5_0\n",
      "appears to be corrupted. The path 'lib/python3.12/site-packages/conda/common/pkg_formats/__init__.py'\n",
      "specified in the package manifest cannot be found.\n",
      "\n",
      "CondaVerificationError: The package for conda located at /opt/anaconda3/pkgs/conda-24.7.1-py312hecd8cb5_0\n",
      "appears to be corrupted. The path 'lib/python3.12/site-packages/conda/common/pkg_formats/__pycache__/python.cpython-312.pyc'\n",
      "specified in the package manifest cannot be found.\n",
      "\n",
      "CondaVerificationError: The package for conda located at /opt/anaconda3/pkgs/conda-24.7.1-py312hecd8cb5_0\n",
      "appears to be corrupted. The path 'lib/python3.12/site-packages/conda/common/pkg_formats/python.py'\n",
      "specified in the package manifest cannot be found.\n",
      "\n",
      "CondaVerificationError: The package for conda located at /opt/anaconda3/pkgs/conda-24.7.1-py312hecd8cb5_0\n",
      "appears to be corrupted. The path 'lib/python3.12/site-packages/conda/common/serialize.py'\n",
      "specified in the package manifest cannot be found.\n",
      "\n",
      "CondaVerificationError: The package for conda located at /opt/anaconda3/pkgs/conda-24.7.1-py312hecd8cb5_0\n",
      "appears to be corrupted. The path 'lib/python3.12/site-packages/conda/common/signals.py'\n",
      "specified in the package manifest cannot be found.\n",
      "\n",
      "CondaVerificationError: The package for conda located at /opt/anaconda3/pkgs/conda-24.7.1-py312hecd8cb5_0\n",
      "appears to be corrupted. The path 'lib/python3.12/site-packages/conda/common/toposort.py'\n",
      "specified in the package manifest cannot be found.\n",
      "\n",
      "CondaVerificationError: The package for conda located at /opt/anaconda3/pkgs/conda-24.7.1-py312hecd8cb5_0\n",
      "appears to be corrupted. The path 'lib/python3.12/site-packages/conda/common/url.py'\n",
      "specified in the package manifest cannot be found.\n",
      "\n",
      "CondaVerificationError: The package for conda located at /opt/anaconda3/pkgs/conda-24.7.1-py312hecd8cb5_0\n",
      "appears to be corrupted. The path 'lib/python3.12/site-packages/conda/core/__init__.py'\n",
      "specified in the package manifest cannot be found.\n",
      "\n",
      "CondaVerificationError: The package for conda located at /opt/anaconda3/pkgs/conda-24.7.1-py312hecd8cb5_0\n",
      "appears to be corrupted. The path 'lib/python3.12/site-packages/conda/core/__pycache__/envs_manager.cpython-312.pyc'\n",
      "specified in the package manifest cannot be found.\n",
      "\n",
      "CondaVerificationError: The package for conda located at /opt/anaconda3/pkgs/conda-24.7.1-py312hecd8cb5_0\n",
      "appears to be corrupted. The path 'lib/python3.12/site-packages/conda/core/__pycache__/index.cpython-312.pyc'\n",
      "specified in the package manifest cannot be found.\n",
      "\n",
      "CondaVerificationError: The package for conda located at /opt/anaconda3/pkgs/conda-24.7.1-py312hecd8cb5_0\n",
      "appears to be corrupted. The path 'lib/python3.12/site-packages/conda/core/__pycache__/initialize.cpython-312.pyc'\n",
      "specified in the package manifest cannot be found.\n",
      "\n",
      "CondaVerificationError: The package for conda located at /opt/anaconda3/pkgs/conda-24.7.1-py312hecd8cb5_0\n",
      "appears to be corrupted. The path 'lib/python3.12/site-packages/conda/core/__pycache__/link.cpython-312.pyc'\n",
      "specified in the package manifest cannot be found.\n",
      "\n",
      "CondaVerificationError: The package for conda located at /opt/anaconda3/pkgs/conda-24.7.1-py312hecd8cb5_0\n",
      "appears to be corrupted. The path 'lib/python3.12/site-packages/conda/core/__pycache__/package_cache_data.cpython-312.pyc'\n",
      "specified in the package manifest cannot be found.\n",
      "\n",
      "CondaVerificationError: The package for conda located at /opt/anaconda3/pkgs/conda-24.7.1-py312hecd8cb5_0\n",
      "appears to be corrupted. The path 'lib/python3.12/site-packages/conda/core/__pycache__/path_actions.cpython-312.pyc'\n",
      "specified in the package manifest cannot be found.\n",
      "\n",
      "CondaVerificationError: The package for conda located at /opt/anaconda3/pkgs/conda-24.7.1-py312hecd8cb5_0\n",
      "appears to be corrupted. The path 'lib/python3.12/site-packages/conda/core/__pycache__/portability.cpython-312.pyc'\n",
      "specified in the package manifest cannot be found.\n",
      "\n",
      "CondaVerificationError: The package for conda located at /opt/anaconda3/pkgs/conda-24.7.1-py312hecd8cb5_0\n",
      "appears to be corrupted. The path 'lib/python3.12/site-packages/conda/core/__pycache__/prefix_data.cpython-312.pyc'\n",
      "specified in the package manifest cannot be found.\n",
      "\n",
      "CondaVerificationError: The package for conda located at /opt/anaconda3/pkgs/conda-24.7.1-py312hecd8cb5_0\n",
      "appears to be corrupted. The path 'lib/python3.12/site-packages/conda/core/__pycache__/solve.cpython-312.pyc'\n",
      "specified in the package manifest cannot be found.\n",
      "\n",
      "CondaVerificationError: The package for conda located at /opt/anaconda3/pkgs/conda-24.7.1-py312hecd8cb5_0\n",
      "appears to be corrupted. The path 'lib/python3.12/site-packages/conda/core/__pycache__/subdir_data.cpython-312.pyc'\n",
      "specified in the package manifest cannot be found.\n",
      "\n",
      "CondaVerificationError: The package for conda located at /opt/anaconda3/pkgs/conda-24.7.1-py312hecd8cb5_0\n",
      "appears to be corrupted. The path 'lib/python3.12/site-packages/conda/core/envs_manager.py'\n",
      "specified in the package manifest cannot be found.\n",
      "\n",
      "CondaVerificationError: The package for conda located at /opt/anaconda3/pkgs/conda-24.7.1-py312hecd8cb5_0\n",
      "appears to be corrupted. The path 'lib/python3.12/site-packages/conda/core/index.py'\n",
      "specified in the package manifest cannot be found.\n",
      "\n",
      "CondaVerificationError: The package for conda located at /opt/anaconda3/pkgs/conda-24.7.1-py312hecd8cb5_0\n",
      "appears to be corrupted. The path 'lib/python3.12/site-packages/conda/core/initialize.py'\n",
      "specified in the package manifest cannot be found.\n",
      "\n",
      "CondaVerificationError: The package for conda located at /opt/anaconda3/pkgs/conda-24.7.1-py312hecd8cb5_0\n",
      "appears to be corrupted. The path 'lib/python3.12/site-packages/conda/core/link.py'\n",
      "specified in the package manifest cannot be found.\n",
      "\n",
      "CondaVerificationError: The package for conda located at /opt/anaconda3/pkgs/conda-24.7.1-py312hecd8cb5_0\n",
      "appears to be corrupted. The path 'lib/python3.12/site-packages/conda/core/package_cache.py'\n",
      "specified in the package manifest cannot be found.\n",
      "\n",
      "CondaVerificationError: The package for conda located at /opt/anaconda3/pkgs/conda-24.7.1-py312hecd8cb5_0\n",
      "appears to be corrupted. The path 'lib/python3.12/site-packages/conda/core/package_cache_data.py'\n",
      "specified in the package manifest cannot be found.\n",
      "\n",
      "CondaVerificationError: The package for conda located at /opt/anaconda3/pkgs/conda-24.7.1-py312hecd8cb5_0\n",
      "appears to be corrupted. The path 'lib/python3.12/site-packages/conda/core/path_actions.py'\n",
      "specified in the package manifest cannot be found.\n",
      "\n",
      "CondaVerificationError: The package for conda located at /opt/anaconda3/pkgs/conda-24.7.1-py312hecd8cb5_0\n",
      "appears to be corrupted. The path 'lib/python3.12/site-packages/conda/core/portability.py'\n",
      "specified in the package manifest cannot be found.\n",
      "\n",
      "CondaVerificationError: The package for conda located at /opt/anaconda3/pkgs/conda-24.7.1-py312hecd8cb5_0\n",
      "appears to be corrupted. The path 'lib/python3.12/site-packages/conda/core/prefix_data.py'\n",
      "specified in the package manifest cannot be found.\n",
      "\n",
      "CondaVerificationError: The package for conda located at /opt/anaconda3/pkgs/conda-24.7.1-py312hecd8cb5_0\n",
      "appears to be corrupted. The path 'lib/python3.12/site-packages/conda/core/solve.py'\n",
      "specified in the package manifest cannot be found.\n",
      "\n",
      "CondaVerificationError: The package for conda located at /opt/anaconda3/pkgs/conda-24.7.1-py312hecd8cb5_0\n",
      "appears to be corrupted. The path 'lib/python3.12/site-packages/conda/core/subdir_data.py'\n",
      "specified in the package manifest cannot be found.\n",
      "\n",
      "CondaVerificationError: The package for conda located at /opt/anaconda3/pkgs/conda-24.7.1-py312hecd8cb5_0\n",
      "appears to be corrupted. The path 'lib/python3.12/site-packages/conda/deprecations.py'\n",
      "specified in the package manifest cannot be found.\n",
      "\n",
      "CondaVerificationError: The package for conda located at /opt/anaconda3/pkgs/conda-24.7.1-py312hecd8cb5_0\n",
      "appears to be corrupted. The path 'lib/python3.12/site-packages/conda/env/__init__.py'\n",
      "specified in the package manifest cannot be found.\n",
      "\n",
      "CondaVerificationError: The package for conda located at /opt/anaconda3/pkgs/conda-24.7.1-py312hecd8cb5_0\n",
      "appears to be corrupted. The path 'lib/python3.12/site-packages/conda/env/__pycache__/env.cpython-312.pyc'\n",
      "specified in the package manifest cannot be found.\n",
      "\n",
      "CondaVerificationError: The package for conda located at /opt/anaconda3/pkgs/conda-24.7.1-py312hecd8cb5_0\n",
      "appears to be corrupted. The path 'lib/python3.12/site-packages/conda/env/env.py'\n",
      "specified in the package manifest cannot be found.\n",
      "\n",
      "CondaVerificationError: The package for conda located at /opt/anaconda3/pkgs/conda-24.7.1-py312hecd8cb5_0\n",
      "appears to be corrupted. The path 'lib/python3.12/site-packages/conda/env/installers/__init__.py'\n",
      "specified in the package manifest cannot be found.\n",
      "\n",
      "CondaVerificationError: The package for conda located at /opt/anaconda3/pkgs/conda-24.7.1-py312hecd8cb5_0\n",
      "appears to be corrupted. The path 'lib/python3.12/site-packages/conda/env/installers/__pycache__/pip.cpython-312.pyc'\n",
      "specified in the package manifest cannot be found.\n",
      "\n",
      "CondaVerificationError: The package for conda located at /opt/anaconda3/pkgs/conda-24.7.1-py312hecd8cb5_0\n",
      "appears to be corrupted. The path 'lib/python3.12/site-packages/conda/env/installers/base.py'\n",
      "specified in the package manifest cannot be found.\n",
      "\n",
      "CondaVerificationError: The package for conda located at /opt/anaconda3/pkgs/conda-24.7.1-py312hecd8cb5_0\n",
      "appears to be corrupted. The path 'lib/python3.12/site-packages/conda/env/installers/conda.py'\n",
      "specified in the package manifest cannot be found.\n",
      "\n",
      "CondaVerificationError: The package for conda located at /opt/anaconda3/pkgs/conda-24.7.1-py312hecd8cb5_0\n",
      "appears to be corrupted. The path 'lib/python3.12/site-packages/conda/env/installers/pip.py'\n",
      "specified in the package manifest cannot be found.\n",
      "\n",
      "CondaVerificationError: The package for conda located at /opt/anaconda3/pkgs/conda-24.7.1-py312hecd8cb5_0\n",
      "appears to be corrupted. The path 'lib/python3.12/site-packages/conda/env/pip_util.py'\n",
      "specified in the package manifest cannot be found.\n",
      "\n",
      "CondaVerificationError: The package for conda located at /opt/anaconda3/pkgs/conda-24.7.1-py312hecd8cb5_0\n",
      "appears to be corrupted. The path 'lib/python3.12/site-packages/conda/env/specs/__init__.py'\n",
      "specified in the package manifest cannot be found.\n",
      "\n",
      "CondaVerificationError: The package for conda located at /opt/anaconda3/pkgs/conda-24.7.1-py312hecd8cb5_0\n",
      "appears to be corrupted. The path 'lib/python3.12/site-packages/conda/env/specs/__pycache__/binstar.cpython-312.pyc'\n",
      "specified in the package manifest cannot be found.\n",
      "\n",
      "CondaVerificationError: The package for conda located at /opt/anaconda3/pkgs/conda-24.7.1-py312hecd8cb5_0\n",
      "appears to be corrupted. The path 'lib/python3.12/site-packages/conda/env/specs/binstar.py'\n",
      "specified in the package manifest cannot be found.\n",
      "\n",
      "CondaVerificationError: The package for conda located at /opt/anaconda3/pkgs/conda-24.7.1-py312hecd8cb5_0\n",
      "appears to be corrupted. The path 'lib/python3.12/site-packages/conda/env/specs/requirements.py'\n",
      "specified in the package manifest cannot be found.\n",
      "\n",
      "CondaVerificationError: The package for conda located at /opt/anaconda3/pkgs/conda-24.7.1-py312hecd8cb5_0\n",
      "appears to be corrupted. The path 'lib/python3.12/site-packages/conda/env/specs/yaml_file.py'\n",
      "specified in the package manifest cannot be found.\n",
      "\n",
      "CondaVerificationError: The package for conda located at /opt/anaconda3/pkgs/conda-24.7.1-py312hecd8cb5_0\n",
      "appears to be corrupted. The path 'lib/python3.12/site-packages/conda/exception_handler.py'\n",
      "specified in the package manifest cannot be found.\n",
      "\n",
      "CondaVerificationError: The package for conda located at /opt/anaconda3/pkgs/conda-24.7.1-py312hecd8cb5_0\n",
      "appears to be corrupted. The path 'lib/python3.12/site-packages/conda/exceptions.py'\n",
      "specified in the package manifest cannot be found.\n",
      "\n",
      "CondaVerificationError: The package for conda located at /opt/anaconda3/pkgs/conda-24.7.1-py312hecd8cb5_0\n",
      "appears to be corrupted. The path 'lib/python3.12/site-packages/conda/exports.py'\n",
      "specified in the package manifest cannot be found.\n",
      "\n",
      "CondaVerificationError: The package for conda located at /opt/anaconda3/pkgs/conda-24.7.1-py312hecd8cb5_0\n",
      "appears to be corrupted. The path 'lib/python3.12/site-packages/conda/gateways/__init__.py'\n",
      "specified in the package manifest cannot be found.\n",
      "\n",
      "CondaVerificationError: The package for conda located at /opt/anaconda3/pkgs/conda-24.7.1-py312hecd8cb5_0\n",
      "appears to be corrupted. The path 'lib/python3.12/site-packages/conda/gateways/__pycache__/anaconda_client.cpython-312.pyc'\n",
      "specified in the package manifest cannot be found.\n",
      "\n",
      "CondaVerificationError: The package for conda located at /opt/anaconda3/pkgs/conda-24.7.1-py312hecd8cb5_0\n",
      "appears to be corrupted. The path 'lib/python3.12/site-packages/conda/gateways/__pycache__/logging.cpython-312.pyc'\n",
      "specified in the package manifest cannot be found.\n",
      "\n",
      "CondaVerificationError: The package for conda located at /opt/anaconda3/pkgs/conda-24.7.1-py312hecd8cb5_0\n",
      "appears to be corrupted. The path 'lib/python3.12/site-packages/conda/gateways/__pycache__/subprocess.cpython-312.pyc'\n",
      "specified in the package manifest cannot be found.\n",
      "\n",
      "CondaVerificationError: The package for conda located at /opt/anaconda3/pkgs/conda-24.7.1-py312hecd8cb5_0\n",
      "appears to be corrupted. The path 'lib/python3.12/site-packages/conda/gateways/anaconda_client.py'\n",
      "specified in the package manifest cannot be found.\n",
      "\n",
      "CondaVerificationError: The package for conda located at /opt/anaconda3/pkgs/conda-24.7.1-py312hecd8cb5_0\n",
      "appears to be corrupted. The path 'lib/python3.12/site-packages/conda/gateways/connection/__init__.py'\n",
      "specified in the package manifest cannot be found.\n",
      "\n",
      "CondaVerificationError: The package for conda located at /opt/anaconda3/pkgs/conda-24.7.1-py312hecd8cb5_0\n",
      "appears to be corrupted. The path 'lib/python3.12/site-packages/conda/gateways/connection/__pycache__/download.cpython-312.pyc'\n",
      "specified in the package manifest cannot be found.\n",
      "\n",
      "CondaVerificationError: The package for conda located at /opt/anaconda3/pkgs/conda-24.7.1-py312hecd8cb5_0\n",
      "appears to be corrupted. The path 'lib/python3.12/site-packages/conda/gateways/connection/__pycache__/session.cpython-312.pyc'\n",
      "specified in the package manifest cannot be found.\n",
      "\n",
      "CondaVerificationError: The package for conda located at /opt/anaconda3/pkgs/conda-24.7.1-py312hecd8cb5_0\n",
      "appears to be corrupted. The path 'lib/python3.12/site-packages/conda/gateways/connection/adapters/__init__.py'\n",
      "specified in the package manifest cannot be found.\n",
      "\n",
      "CondaVerificationError: The package for conda located at /opt/anaconda3/pkgs/conda-24.7.1-py312hecd8cb5_0\n",
      "appears to be corrupted. The path 'lib/python3.12/site-packages/conda/gateways/connection/adapters/__pycache__/ftp.cpython-312.pyc'\n",
      "specified in the package manifest cannot be found.\n",
      "\n",
      "CondaVerificationError: The package for conda located at /opt/anaconda3/pkgs/conda-24.7.1-py312hecd8cb5_0\n",
      "appears to be corrupted. The path 'lib/python3.12/site-packages/conda/gateways/connection/adapters/__pycache__/s3.cpython-312.pyc'\n",
      "specified in the package manifest cannot be found.\n",
      "\n",
      "CondaVerificationError: The package for conda located at /opt/anaconda3/pkgs/conda-24.7.1-py312hecd8cb5_0\n",
      "appears to be corrupted. The path 'lib/python3.12/site-packages/conda/gateways/connection/adapters/ftp.py'\n",
      "specified in the package manifest cannot be found.\n",
      "\n",
      "CondaVerificationError: The package for conda located at /opt/anaconda3/pkgs/conda-24.7.1-py312hecd8cb5_0\n",
      "appears to be corrupted. The path 'lib/python3.12/site-packages/conda/gateways/connection/adapters/http.py'\n",
      "specified in the package manifest cannot be found.\n",
      "\n",
      "CondaVerificationError: The package for conda located at /opt/anaconda3/pkgs/conda-24.7.1-py312hecd8cb5_0\n",
      "appears to be corrupted. The path 'lib/python3.12/site-packages/conda/gateways/connection/adapters/localfs.py'\n",
      "specified in the package manifest cannot be found.\n",
      "\n",
      "CondaVerificationError: The package for conda located at /opt/anaconda3/pkgs/conda-24.7.1-py312hecd8cb5_0\n",
      "appears to be corrupted. The path 'lib/python3.12/site-packages/conda/gateways/connection/adapters/s3.py'\n",
      "specified in the package manifest cannot be found.\n",
      "\n",
      "CondaVerificationError: The package for conda located at /opt/anaconda3/pkgs/conda-24.7.1-py312hecd8cb5_0\n",
      "appears to be corrupted. The path 'lib/python3.12/site-packages/conda/gateways/connection/download.py'\n",
      "specified in the package manifest cannot be found.\n",
      "\n",
      "CondaVerificationError: The package for conda located at /opt/anaconda3/pkgs/conda-24.7.1-py312hecd8cb5_0\n",
      "appears to be corrupted. The path 'lib/python3.12/site-packages/conda/gateways/connection/session.py'\n",
      "specified in the package manifest cannot be found.\n",
      "\n",
      "CondaVerificationError: The package for conda located at /opt/anaconda3/pkgs/conda-24.7.1-py312hecd8cb5_0\n",
      "appears to be corrupted. The path 'lib/python3.12/site-packages/conda/gateways/disk/__init__.py'\n",
      "specified in the package manifest cannot be found.\n",
      "\n",
      "CondaVerificationError: The package for conda located at /opt/anaconda3/pkgs/conda-24.7.1-py312hecd8cb5_0\n",
      "appears to be corrupted. The path 'lib/python3.12/site-packages/conda/gateways/disk/__pycache__/__init__.cpython-312.pyc'\n",
      "specified in the package manifest cannot be found.\n",
      "\n",
      "CondaVerificationError: The package for conda located at /opt/anaconda3/pkgs/conda-24.7.1-py312hecd8cb5_0\n",
      "appears to be corrupted. The path 'lib/python3.12/site-packages/conda/gateways/disk/__pycache__/create.cpython-312.pyc'\n",
      "specified in the package manifest cannot be found.\n",
      "\n",
      "CondaVerificationError: The package for conda located at /opt/anaconda3/pkgs/conda-24.7.1-py312hecd8cb5_0\n",
      "appears to be corrupted. The path 'lib/python3.12/site-packages/conda/gateways/disk/__pycache__/delete.cpython-312.pyc'\n",
      "specified in the package manifest cannot be found.\n",
      "\n",
      "CondaVerificationError: The package for conda located at /opt/anaconda3/pkgs/conda-24.7.1-py312hecd8cb5_0\n",
      "appears to be corrupted. The path 'lib/python3.12/site-packages/conda/gateways/disk/__pycache__/link.cpython-312.pyc'\n",
      "specified in the package manifest cannot be found.\n",
      "\n",
      "CondaVerificationError: The package for conda located at /opt/anaconda3/pkgs/conda-24.7.1-py312hecd8cb5_0\n",
      "appears to be corrupted. The path 'lib/python3.12/site-packages/conda/gateways/disk/__pycache__/lock.cpython-312.pyc'\n",
      "specified in the package manifest cannot be found.\n",
      "\n",
      "CondaVerificationError: The package for conda located at /opt/anaconda3/pkgs/conda-24.7.1-py312hecd8cb5_0\n",
      "appears to be corrupted. The path 'lib/python3.12/site-packages/conda/gateways/disk/__pycache__/permissions.cpython-312.pyc'\n",
      "specified in the package manifest cannot be found.\n",
      "\n",
      "CondaVerificationError: The package for conda located at /opt/anaconda3/pkgs/conda-24.7.1-py312hecd8cb5_0\n",
      "appears to be corrupted. The path 'lib/python3.12/site-packages/conda/gateways/disk/__pycache__/read.cpython-312.pyc'\n",
      "specified in the package manifest cannot be found.\n",
      "\n",
      "CondaVerificationError: The package for conda located at /opt/anaconda3/pkgs/conda-24.7.1-py312hecd8cb5_0\n",
      "appears to be corrupted. The path 'lib/python3.12/site-packages/conda/gateways/disk/__pycache__/test.cpython-312.pyc'\n",
      "specified in the package manifest cannot be found.\n",
      "\n",
      "CondaVerificationError: The package for conda located at /opt/anaconda3/pkgs/conda-24.7.1-py312hecd8cb5_0\n",
      "appears to be corrupted. The path 'lib/python3.12/site-packages/conda/gateways/disk/__pycache__/update.cpython-312.pyc'\n",
      "specified in the package manifest cannot be found.\n",
      "\n",
      "CondaVerificationError: The package for conda located at /opt/anaconda3/pkgs/conda-24.7.1-py312hecd8cb5_0\n",
      "appears to be corrupted. The path 'lib/python3.12/site-packages/conda/gateways/disk/create.py'\n",
      "specified in the package manifest cannot be found.\n",
      "\n",
      "CondaVerificationError: The package for conda located at /opt/anaconda3/pkgs/conda-24.7.1-py312hecd8cb5_0\n",
      "appears to be corrupted. The path 'lib/python3.12/site-packages/conda/gateways/disk/delete.py'\n",
      "specified in the package manifest cannot be found.\n",
      "\n",
      "CondaVerificationError: The package for conda located at /opt/anaconda3/pkgs/conda-24.7.1-py312hecd8cb5_0\n",
      "appears to be corrupted. The path 'lib/python3.12/site-packages/conda/gateways/disk/link.py'\n",
      "specified in the package manifest cannot be found.\n",
      "\n",
      "CondaVerificationError: The package for conda located at /opt/anaconda3/pkgs/conda-24.7.1-py312hecd8cb5_0\n",
      "appears to be corrupted. The path 'lib/python3.12/site-packages/conda/gateways/disk/lock.py'\n",
      "specified in the package manifest cannot be found.\n",
      "\n",
      "CondaVerificationError: The package for conda located at /opt/anaconda3/pkgs/conda-24.7.1-py312hecd8cb5_0\n",
      "appears to be corrupted. The path 'lib/python3.12/site-packages/conda/gateways/disk/permissions.py'\n",
      "specified in the package manifest cannot be found.\n",
      "\n",
      "CondaVerificationError: The package for conda located at /opt/anaconda3/pkgs/conda-24.7.1-py312hecd8cb5_0\n",
      "appears to be corrupted. The path 'lib/python3.12/site-packages/conda/gateways/disk/read.py'\n",
      "specified in the package manifest cannot be found.\n",
      "\n",
      "CondaVerificationError: The package for conda located at /opt/anaconda3/pkgs/conda-24.7.1-py312hecd8cb5_0\n",
      "appears to be corrupted. The path 'lib/python3.12/site-packages/conda/gateways/disk/test.py'\n",
      "specified in the package manifest cannot be found.\n",
      "\n",
      "CondaVerificationError: The package for conda located at /opt/anaconda3/pkgs/conda-24.7.1-py312hecd8cb5_0\n",
      "appears to be corrupted. The path 'lib/python3.12/site-packages/conda/gateways/disk/update.py'\n",
      "specified in the package manifest cannot be found.\n",
      "\n",
      "CondaVerificationError: The package for conda located at /opt/anaconda3/pkgs/conda-24.7.1-py312hecd8cb5_0\n",
      "appears to be corrupted. The path 'lib/python3.12/site-packages/conda/gateways/logging.py'\n",
      "specified in the package manifest cannot be found.\n",
      "\n",
      "CondaVerificationError: The package for conda located at /opt/anaconda3/pkgs/conda-24.7.1-py312hecd8cb5_0\n",
      "appears to be corrupted. The path 'lib/python3.12/site-packages/conda/gateways/repodata/__init__.py'\n",
      "specified in the package manifest cannot be found.\n",
      "\n",
      "CondaVerificationError: The package for conda located at /opt/anaconda3/pkgs/conda-24.7.1-py312hecd8cb5_0\n",
      "appears to be corrupted. The path 'lib/python3.12/site-packages/conda/gateways/repodata/__pycache__/__init__.cpython-312.pyc'\n",
      "specified in the package manifest cannot be found.\n",
      "\n",
      "CondaVerificationError: The package for conda located at /opt/anaconda3/pkgs/conda-24.7.1-py312hecd8cb5_0\n",
      "appears to be corrupted. The path 'lib/python3.12/site-packages/conda/gateways/repodata/jlap/__init__.py'\n",
      "specified in the package manifest cannot be found.\n",
      "\n",
      "CondaVerificationError: The package for conda located at /opt/anaconda3/pkgs/conda-24.7.1-py312hecd8cb5_0\n",
      "appears to be corrupted. The path 'lib/python3.12/site-packages/conda/gateways/repodata/jlap/__pycache__/core.cpython-312.pyc'\n",
      "specified in the package manifest cannot be found.\n",
      "\n",
      "CondaVerificationError: The package for conda located at /opt/anaconda3/pkgs/conda-24.7.1-py312hecd8cb5_0\n",
      "appears to be corrupted. The path 'lib/python3.12/site-packages/conda/gateways/repodata/jlap/__pycache__/fetch.cpython-312.pyc'\n",
      "specified in the package manifest cannot be found.\n",
      "\n",
      "CondaVerificationError: The package for conda located at /opt/anaconda3/pkgs/conda-24.7.1-py312hecd8cb5_0\n",
      "appears to be corrupted. The path 'lib/python3.12/site-packages/conda/gateways/repodata/jlap/__pycache__/interface.cpython-312.pyc'\n",
      "specified in the package manifest cannot be found.\n",
      "\n",
      "CondaVerificationError: The package for conda located at /opt/anaconda3/pkgs/conda-24.7.1-py312hecd8cb5_0\n",
      "appears to be corrupted. The path 'lib/python3.12/site-packages/conda/gateways/repodata/jlap/core.py'\n",
      "specified in the package manifest cannot be found.\n",
      "\n",
      "CondaVerificationError: The package for conda located at /opt/anaconda3/pkgs/conda-24.7.1-py312hecd8cb5_0\n",
      "appears to be corrupted. The path 'lib/python3.12/site-packages/conda/gateways/repodata/jlap/fetch.py'\n",
      "specified in the package manifest cannot be found.\n",
      "\n",
      "CondaVerificationError: The package for conda located at /opt/anaconda3/pkgs/conda-24.7.1-py312hecd8cb5_0\n",
      "appears to be corrupted. The path 'lib/python3.12/site-packages/conda/gateways/repodata/jlap/interface.py'\n",
      "specified in the package manifest cannot be found.\n",
      "\n",
      "CondaVerificationError: The package for conda located at /opt/anaconda3/pkgs/conda-24.7.1-py312hecd8cb5_0\n",
      "appears to be corrupted. The path 'lib/python3.12/site-packages/conda/gateways/repodata/lock.py'\n",
      "specified in the package manifest cannot be found.\n",
      "\n",
      "CondaVerificationError: The package for conda located at /opt/anaconda3/pkgs/conda-24.7.1-py312hecd8cb5_0\n",
      "appears to be corrupted. The path 'lib/python3.12/site-packages/conda/gateways/subprocess.py'\n",
      "specified in the package manifest cannot be found.\n",
      "\n",
      "CondaVerificationError: The package for conda located at /opt/anaconda3/pkgs/conda-24.7.1-py312hecd8cb5_0\n",
      "appears to be corrupted. The path 'lib/python3.12/site-packages/conda/history.py'\n",
      "specified in the package manifest cannot be found.\n",
      "\n",
      "CondaVerificationError: The package for conda located at /opt/anaconda3/pkgs/conda-24.7.1-py312hecd8cb5_0\n",
      "appears to be corrupted. The path 'lib/python3.12/site-packages/conda/instructions.py'\n",
      "specified in the package manifest cannot be found.\n",
      "\n",
      "CondaVerificationError: The package for conda located at /opt/anaconda3/pkgs/conda-24.7.1-py312hecd8cb5_0\n",
      "appears to be corrupted. The path 'lib/python3.12/site-packages/conda/misc.py'\n",
      "specified in the package manifest cannot be found.\n",
      "\n",
      "CondaVerificationError: The package for conda located at /opt/anaconda3/pkgs/conda-24.7.1-py312hecd8cb5_0\n",
      "appears to be corrupted. The path 'lib/python3.12/site-packages/conda/models/__init__.py'\n",
      "specified in the package manifest cannot be found.\n",
      "\n",
      "CondaVerificationError: The package for conda located at /opt/anaconda3/pkgs/conda-24.7.1-py312hecd8cb5_0\n",
      "appears to be corrupted. The path 'lib/python3.12/site-packages/conda/models/__pycache__/channel.cpython-312.pyc'\n",
      "specified in the package manifest cannot be found.\n",
      "\n",
      "CondaVerificationError: The package for conda located at /opt/anaconda3/pkgs/conda-24.7.1-py312hecd8cb5_0\n",
      "appears to be corrupted. The path 'lib/python3.12/site-packages/conda/models/__pycache__/dist.cpython-312.pyc'\n",
      "specified in the package manifest cannot be found.\n",
      "\n",
      "CondaVerificationError: The package for conda located at /opt/anaconda3/pkgs/conda-24.7.1-py312hecd8cb5_0\n",
      "appears to be corrupted. The path 'lib/python3.12/site-packages/conda/models/__pycache__/enums.cpython-312.pyc'\n",
      "specified in the package manifest cannot be found.\n",
      "\n",
      "CondaVerificationError: The package for conda located at /opt/anaconda3/pkgs/conda-24.7.1-py312hecd8cb5_0\n",
      "appears to be corrupted. The path 'lib/python3.12/site-packages/conda/models/__pycache__/match_spec.cpython-312.pyc'\n",
      "specified in the package manifest cannot be found.\n",
      "\n",
      "CondaVerificationError: The package for conda located at /opt/anaconda3/pkgs/conda-24.7.1-py312hecd8cb5_0\n",
      "appears to be corrupted. The path 'lib/python3.12/site-packages/conda/models/__pycache__/package_info.cpython-312.pyc'\n",
      "specified in the package manifest cannot be found.\n",
      "\n",
      "CondaVerificationError: The package for conda located at /opt/anaconda3/pkgs/conda-24.7.1-py312hecd8cb5_0\n",
      "appears to be corrupted. The path 'lib/python3.12/site-packages/conda/models/__pycache__/prefix_graph.cpython-312.pyc'\n",
      "specified in the package manifest cannot be found.\n",
      "\n",
      "CondaVerificationError: The package for conda located at /opt/anaconda3/pkgs/conda-24.7.1-py312hecd8cb5_0\n",
      "appears to be corrupted. The path 'lib/python3.12/site-packages/conda/models/__pycache__/records.cpython-312.pyc'\n",
      "specified in the package manifest cannot be found.\n",
      "\n",
      "CondaVerificationError: The package for conda located at /opt/anaconda3/pkgs/conda-24.7.1-py312hecd8cb5_0\n",
      "appears to be corrupted. The path 'lib/python3.12/site-packages/conda/models/__pycache__/version.cpython-312.pyc'\n",
      "specified in the package manifest cannot be found.\n",
      "\n",
      "CondaVerificationError: The package for conda located at /opt/anaconda3/pkgs/conda-24.7.1-py312hecd8cb5_0\n",
      "appears to be corrupted. The path 'lib/python3.12/site-packages/conda/models/channel.py'\n",
      "specified in the package manifest cannot be found.\n",
      "\n",
      "CondaVerificationError: The package for conda located at /opt/anaconda3/pkgs/conda-24.7.1-py312hecd8cb5_0\n",
      "appears to be corrupted. The path 'lib/python3.12/site-packages/conda/models/dist.py'\n",
      "specified in the package manifest cannot be found.\n",
      "\n",
      "CondaVerificationError: The package for conda located at /opt/anaconda3/pkgs/conda-24.7.1-py312hecd8cb5_0\n",
      "appears to be corrupted. The path 'lib/python3.12/site-packages/conda/models/enums.py'\n",
      "specified in the package manifest cannot be found.\n",
      "\n",
      "CondaVerificationError: The package for conda located at /opt/anaconda3/pkgs/conda-24.7.1-py312hecd8cb5_0\n",
      "appears to be corrupted. The path 'lib/python3.12/site-packages/conda/models/leased_path_entry.py'\n",
      "specified in the package manifest cannot be found.\n",
      "\n",
      "CondaVerificationError: The package for conda located at /opt/anaconda3/pkgs/conda-24.7.1-py312hecd8cb5_0\n",
      "appears to be corrupted. The path 'lib/python3.12/site-packages/conda/models/match_spec.py'\n",
      "specified in the package manifest cannot be found.\n",
      "\n",
      "CondaVerificationError: The package for conda located at /opt/anaconda3/pkgs/conda-24.7.1-py312hecd8cb5_0\n",
      "appears to be corrupted. The path 'lib/python3.12/site-packages/conda/models/package_info.py'\n",
      "specified in the package manifest cannot be found.\n",
      "\n",
      "CondaVerificationError: The package for conda located at /opt/anaconda3/pkgs/conda-24.7.1-py312hecd8cb5_0\n",
      "appears to be corrupted. The path 'lib/python3.12/site-packages/conda/models/prefix_graph.py'\n",
      "specified in the package manifest cannot be found.\n",
      "\n",
      "CondaVerificationError: The package for conda located at /opt/anaconda3/pkgs/conda-24.7.1-py312hecd8cb5_0\n",
      "appears to be corrupted. The path 'lib/python3.12/site-packages/conda/models/records.py'\n",
      "specified in the package manifest cannot be found.\n",
      "\n",
      "CondaVerificationError: The package for conda located at /opt/anaconda3/pkgs/conda-24.7.1-py312hecd8cb5_0\n",
      "appears to be corrupted. The path 'lib/python3.12/site-packages/conda/models/version.py'\n",
      "specified in the package manifest cannot be found.\n",
      "\n",
      "CondaVerificationError: The package for conda located at /opt/anaconda3/pkgs/conda-24.7.1-py312hecd8cb5_0\n",
      "appears to be corrupted. The path 'lib/python3.12/site-packages/conda/notices/__init__.py'\n",
      "specified in the package manifest cannot be found.\n",
      "\n",
      "CondaVerificationError: The package for conda located at /opt/anaconda3/pkgs/conda-24.7.1-py312hecd8cb5_0\n",
      "appears to be corrupted. The path 'lib/python3.12/site-packages/conda/notices/__pycache__/cache.cpython-312.pyc'\n",
      "specified in the package manifest cannot be found.\n",
      "\n",
      "CondaVerificationError: The package for conda located at /opt/anaconda3/pkgs/conda-24.7.1-py312hecd8cb5_0\n",
      "appears to be corrupted. The path 'lib/python3.12/site-packages/conda/notices/__pycache__/core.cpython-312.pyc'\n",
      "specified in the package manifest cannot be found.\n",
      "\n",
      "CondaVerificationError: The package for conda located at /opt/anaconda3/pkgs/conda-24.7.1-py312hecd8cb5_0\n",
      "appears to be corrupted. The path 'lib/python3.12/site-packages/conda/notices/__pycache__/fetch.cpython-312.pyc'\n",
      "specified in the package manifest cannot be found.\n",
      "\n",
      "CondaVerificationError: The package for conda located at /opt/anaconda3/pkgs/conda-24.7.1-py312hecd8cb5_0\n",
      "appears to be corrupted. The path 'lib/python3.12/site-packages/conda/notices/__pycache__/types.cpython-312.pyc'\n",
      "specified in the package manifest cannot be found.\n",
      "\n",
      "CondaVerificationError: The package for conda located at /opt/anaconda3/pkgs/conda-24.7.1-py312hecd8cb5_0\n",
      "appears to be corrupted. The path 'lib/python3.12/site-packages/conda/notices/cache.py'\n",
      "specified in the package manifest cannot be found.\n",
      "\n",
      "CondaVerificationError: The package for conda located at /opt/anaconda3/pkgs/conda-24.7.1-py312hecd8cb5_0\n",
      "appears to be corrupted. The path 'lib/python3.12/site-packages/conda/notices/core.py'\n",
      "specified in the package manifest cannot be found.\n",
      "\n",
      "CondaVerificationError: The package for conda located at /opt/anaconda3/pkgs/conda-24.7.1-py312hecd8cb5_0\n",
      "appears to be corrupted. The path 'lib/python3.12/site-packages/conda/notices/fetch.py'\n",
      "specified in the package manifest cannot be found.\n",
      "\n",
      "CondaVerificationError: The package for conda located at /opt/anaconda3/pkgs/conda-24.7.1-py312hecd8cb5_0\n",
      "appears to be corrupted. The path 'lib/python3.12/site-packages/conda/notices/types.py'\n",
      "specified in the package manifest cannot be found.\n",
      "\n",
      "CondaVerificationError: The package for conda located at /opt/anaconda3/pkgs/conda-24.7.1-py312hecd8cb5_0\n",
      "appears to be corrupted. The path 'lib/python3.12/site-packages/conda/notices/views.py'\n",
      "specified in the package manifest cannot be found.\n",
      "\n",
      "CondaVerificationError: The package for conda located at /opt/anaconda3/pkgs/conda-24.7.1-py312hecd8cb5_0\n",
      "appears to be corrupted. The path 'lib/python3.12/site-packages/conda/plan.py'\n",
      "specified in the package manifest cannot be found.\n",
      "\n",
      "CondaVerificationError: The package for conda located at /opt/anaconda3/pkgs/conda-24.7.1-py312hecd8cb5_0\n",
      "appears to be corrupted. The path 'lib/python3.12/site-packages/conda/plugins/__init__.py'\n",
      "specified in the package manifest cannot be found.\n",
      "\n",
      "CondaVerificationError: The package for conda located at /opt/anaconda3/pkgs/conda-24.7.1-py312hecd8cb5_0\n",
      "appears to be corrupted. The path 'lib/python3.12/site-packages/conda/plugins/__pycache__/hookspec.cpython-312.pyc'\n",
      "specified in the package manifest cannot be found.\n",
      "\n",
      "CondaVerificationError: The package for conda located at /opt/anaconda3/pkgs/conda-24.7.1-py312hecd8cb5_0\n",
      "appears to be corrupted. The path 'lib/python3.12/site-packages/conda/plugins/__pycache__/manager.cpython-312.pyc'\n",
      "specified in the package manifest cannot be found.\n",
      "\n",
      "CondaVerificationError: The package for conda located at /opt/anaconda3/pkgs/conda-24.7.1-py312hecd8cb5_0\n",
      "appears to be corrupted. The path 'lib/python3.12/site-packages/conda/plugins/__pycache__/types.cpython-312.pyc'\n",
      "specified in the package manifest cannot be found.\n",
      "\n",
      "CondaVerificationError: The package for conda located at /opt/anaconda3/pkgs/conda-24.7.1-py312hecd8cb5_0\n",
      "appears to be corrupted. The path 'lib/python3.12/site-packages/conda/plugins/hookspec.py'\n",
      "specified in the package manifest cannot be found.\n",
      "\n",
      "CondaVerificationError: The package for conda located at /opt/anaconda3/pkgs/conda-24.7.1-py312hecd8cb5_0\n",
      "appears to be corrupted. The path 'lib/python3.12/site-packages/conda/plugins/manager.py'\n",
      "specified in the package manifest cannot be found.\n",
      "\n",
      "CondaVerificationError: The package for conda located at /opt/anaconda3/pkgs/conda-24.7.1-py312hecd8cb5_0\n",
      "appears to be corrupted. The path 'lib/python3.12/site-packages/conda/plugins/post_solves/__init__.py'\n",
      "specified in the package manifest cannot be found.\n",
      "\n",
      "CondaVerificationError: The package for conda located at /opt/anaconda3/pkgs/conda-24.7.1-py312hecd8cb5_0\n",
      "appears to be corrupted. The path 'lib/python3.12/site-packages/conda/plugins/post_solves/signature_verification.py'\n",
      "specified in the package manifest cannot be found.\n",
      "\n",
      "CondaVerificationError: The package for conda located at /opt/anaconda3/pkgs/conda-24.7.1-py312hecd8cb5_0\n",
      "appears to be corrupted. The path 'lib/python3.12/site-packages/conda/plugins/solvers.py'\n",
      "specified in the package manifest cannot be found.\n",
      "\n",
      "CondaVerificationError: The package for conda located at /opt/anaconda3/pkgs/conda-24.7.1-py312hecd8cb5_0\n",
      "appears to be corrupted. The path 'lib/python3.12/site-packages/conda/plugins/subcommands/__init__.py'\n",
      "specified in the package manifest cannot be found.\n",
      "\n",
      "CondaVerificationError: The package for conda located at /opt/anaconda3/pkgs/conda-24.7.1-py312hecd8cb5_0\n",
      "appears to be corrupted. The path 'lib/python3.12/site-packages/conda/plugins/subcommands/doctor/__init__.py'\n",
      "specified in the package manifest cannot be found.\n",
      "\n",
      "CondaVerificationError: The package for conda located at /opt/anaconda3/pkgs/conda-24.7.1-py312hecd8cb5_0\n",
      "appears to be corrupted. The path 'lib/python3.12/site-packages/conda/plugins/subcommands/doctor/__pycache__/health_checks.cpython-312.pyc'\n",
      "specified in the package manifest cannot be found.\n",
      "\n",
      "CondaVerificationError: The package for conda located at /opt/anaconda3/pkgs/conda-24.7.1-py312hecd8cb5_0\n",
      "appears to be corrupted. The path 'lib/python3.12/site-packages/conda/plugins/subcommands/doctor/health_checks.py'\n",
      "specified in the package manifest cannot be found.\n",
      "\n",
      "CondaVerificationError: The package for conda located at /opt/anaconda3/pkgs/conda-24.7.1-py312hecd8cb5_0\n",
      "appears to be corrupted. The path 'lib/python3.12/site-packages/conda/plugins/types.py'\n",
      "specified in the package manifest cannot be found.\n",
      "\n",
      "CondaVerificationError: The package for conda located at /opt/anaconda3/pkgs/conda-24.7.1-py312hecd8cb5_0\n",
      "appears to be corrupted. The path 'lib/python3.12/site-packages/conda/plugins/virtual_packages/__init__.py'\n",
      "specified in the package manifest cannot be found.\n",
      "\n",
      "CondaVerificationError: The package for conda located at /opt/anaconda3/pkgs/conda-24.7.1-py312hecd8cb5_0\n",
      "appears to be corrupted. The path 'lib/python3.12/site-packages/conda/plugins/virtual_packages/__pycache__/cuda.cpython-312.pyc'\n",
      "specified in the package manifest cannot be found.\n",
      "\n",
      "CondaVerificationError: The package for conda located at /opt/anaconda3/pkgs/conda-24.7.1-py312hecd8cb5_0\n",
      "appears to be corrupted. The path 'lib/python3.12/site-packages/conda/plugins/virtual_packages/archspec.py'\n",
      "specified in the package manifest cannot be found.\n",
      "\n",
      "CondaVerificationError: The package for conda located at /opt/anaconda3/pkgs/conda-24.7.1-py312hecd8cb5_0\n",
      "appears to be corrupted. The path 'lib/python3.12/site-packages/conda/plugins/virtual_packages/conda.py'\n",
      "specified in the package manifest cannot be found.\n",
      "\n",
      "CondaVerificationError: The package for conda located at /opt/anaconda3/pkgs/conda-24.7.1-py312hecd8cb5_0\n",
      "appears to be corrupted. The path 'lib/python3.12/site-packages/conda/plugins/virtual_packages/cuda.py'\n",
      "specified in the package manifest cannot be found.\n",
      "\n",
      "CondaVerificationError: The package for conda located at /opt/anaconda3/pkgs/conda-24.7.1-py312hecd8cb5_0\n",
      "appears to be corrupted. The path 'lib/python3.12/site-packages/conda/plugins/virtual_packages/freebsd.py'\n",
      "specified in the package manifest cannot be found.\n",
      "\n",
      "CondaVerificationError: The package for conda located at /opt/anaconda3/pkgs/conda-24.7.1-py312hecd8cb5_0\n",
      "appears to be corrupted. The path 'lib/python3.12/site-packages/conda/plugins/virtual_packages/linux.py'\n",
      "specified in the package manifest cannot be found.\n",
      "\n",
      "CondaVerificationError: The package for conda located at /opt/anaconda3/pkgs/conda-24.7.1-py312hecd8cb5_0\n",
      "appears to be corrupted. The path 'lib/python3.12/site-packages/conda/plugins/virtual_packages/osx.py'\n",
      "specified in the package manifest cannot be found.\n",
      "\n",
      "CondaVerificationError: The package for conda located at /opt/anaconda3/pkgs/conda-24.7.1-py312hecd8cb5_0\n",
      "appears to be corrupted. The path 'lib/python3.12/site-packages/conda/plugins/virtual_packages/windows.py'\n",
      "specified in the package manifest cannot be found.\n",
      "\n",
      "CondaVerificationError: The package for conda located at /opt/anaconda3/pkgs/conda-24.7.1-py312hecd8cb5_0\n",
      "appears to be corrupted. The path 'lib/python3.12/site-packages/conda/py.typed'\n",
      "specified in the package manifest cannot be found.\n",
      "\n",
      "CondaVerificationError: The package for conda located at /opt/anaconda3/pkgs/conda-24.7.1-py312hecd8cb5_0\n",
      "appears to be corrupted. The path 'lib/python3.12/site-packages/conda/resolve.py'\n",
      "specified in the package manifest cannot be found.\n",
      "\n",
      "CondaVerificationError: The package for conda located at /opt/anaconda3/pkgs/conda-24.7.1-py312hecd8cb5_0\n",
      "appears to be corrupted. The path 'lib/python3.12/site-packages/conda/shell/Library/bin/conda.bat'\n",
      "specified in the package manifest cannot be found.\n",
      "\n",
      "CondaVerificationError: The package for conda located at /opt/anaconda3/pkgs/conda-24.7.1-py312hecd8cb5_0\n",
      "appears to be corrupted. The path 'lib/python3.12/site-packages/conda/shell/Scripts/activate.bat'\n",
      "specified in the package manifest cannot be found.\n",
      "\n",
      "CondaVerificationError: The package for conda located at /opt/anaconda3/pkgs/conda-24.7.1-py312hecd8cb5_0\n",
      "appears to be corrupted. The path 'lib/python3.12/site-packages/conda/shell/bin/activate'\n",
      "specified in the package manifest cannot be found.\n",
      "\n",
      "CondaVerificationError: The package for conda located at /opt/anaconda3/pkgs/conda-24.7.1-py312hecd8cb5_0\n",
      "appears to be corrupted. The path 'lib/python3.12/site-packages/conda/shell/bin/conda'\n",
      "specified in the package manifest cannot be found.\n",
      "\n",
      "CondaVerificationError: The package for conda located at /opt/anaconda3/pkgs/conda-24.7.1-py312hecd8cb5_0\n",
      "appears to be corrupted. The path 'lib/python3.12/site-packages/conda/shell/bin/deactivate'\n",
      "specified in the package manifest cannot be found.\n",
      "\n",
      "CondaVerificationError: The package for conda located at /opt/anaconda3/pkgs/conda-24.7.1-py312hecd8cb5_0\n",
      "appears to be corrupted. The path 'lib/python3.12/site-packages/conda/shell/cli-32.exe'\n",
      "specified in the package manifest cannot be found.\n",
      "\n",
      "CondaVerificationError: The package for conda located at /opt/anaconda3/pkgs/conda-24.7.1-py312hecd8cb5_0\n",
      "appears to be corrupted. The path 'lib/python3.12/site-packages/conda/shell/cli-64.exe'\n",
      "specified in the package manifest cannot be found.\n",
      "\n",
      "CondaVerificationError: The package for conda located at /opt/anaconda3/pkgs/conda-24.7.1-py312hecd8cb5_0\n",
      "appears to be corrupted. The path 'lib/python3.12/site-packages/conda/shell/conda.xsh'\n",
      "specified in the package manifest cannot be found.\n",
      "\n",
      "CondaVerificationError: The package for conda located at /opt/anaconda3/pkgs/conda-24.7.1-py312hecd8cb5_0\n",
      "appears to be corrupted. The path 'lib/python3.12/site-packages/conda/shell/conda_icon.ico'\n",
      "specified in the package manifest cannot be found.\n",
      "\n",
      "CondaVerificationError: The package for conda located at /opt/anaconda3/pkgs/conda-24.7.1-py312hecd8cb5_0\n",
      "appears to be corrupted. The path 'lib/python3.12/site-packages/conda/shell/condabin/Conda.psm1'\n",
      "specified in the package manifest cannot be found.\n",
      "\n",
      "CondaVerificationError: The package for conda located at /opt/anaconda3/pkgs/conda-24.7.1-py312hecd8cb5_0\n",
      "appears to be corrupted. The path 'lib/python3.12/site-packages/conda/shell/condabin/_conda_activate.bat'\n",
      "specified in the package manifest cannot be found.\n",
      "\n",
      "CondaVerificationError: The package for conda located at /opt/anaconda3/pkgs/conda-24.7.1-py312hecd8cb5_0\n",
      "appears to be corrupted. The path 'lib/python3.12/site-packages/conda/shell/condabin/activate.bat'\n",
      "specified in the package manifest cannot be found.\n",
      "\n",
      "CondaVerificationError: The package for conda located at /opt/anaconda3/pkgs/conda-24.7.1-py312hecd8cb5_0\n",
      "appears to be corrupted. The path 'lib/python3.12/site-packages/conda/shell/condabin/conda-hook.ps1'\n",
      "specified in the package manifest cannot be found.\n",
      "\n",
      "CondaVerificationError: The package for conda located at /opt/anaconda3/pkgs/conda-24.7.1-py312hecd8cb5_0\n",
      "appears to be corrupted. The path 'lib/python3.12/site-packages/conda/shell/condabin/conda.bat'\n",
      "specified in the package manifest cannot be found.\n",
      "\n",
      "CondaVerificationError: The package for conda located at /opt/anaconda3/pkgs/conda-24.7.1-py312hecd8cb5_0\n",
      "appears to be corrupted. The path 'lib/python3.12/site-packages/conda/shell/condabin/conda_auto_activate.bat'\n",
      "specified in the package manifest cannot be found.\n",
      "\n",
      "CondaVerificationError: The package for conda located at /opt/anaconda3/pkgs/conda-24.7.1-py312hecd8cb5_0\n",
      "appears to be corrupted. The path 'lib/python3.12/site-packages/conda/shell/condabin/conda_hook.bat'\n",
      "specified in the package manifest cannot be found.\n",
      "\n",
      "CondaVerificationError: The package for conda located at /opt/anaconda3/pkgs/conda-24.7.1-py312hecd8cb5_0\n",
      "appears to be corrupted. The path 'lib/python3.12/site-packages/conda/shell/condabin/deactivate.bat'\n",
      "specified in the package manifest cannot be found.\n",
      "\n",
      "CondaVerificationError: The package for conda located at /opt/anaconda3/pkgs/conda-24.7.1-py312hecd8cb5_0\n",
      "appears to be corrupted. The path 'lib/python3.12/site-packages/conda/shell/condabin/rename_tmp.bat'\n",
      "specified in the package manifest cannot be found.\n",
      "\n",
      "CondaVerificationError: The package for conda located at /opt/anaconda3/pkgs/conda-24.7.1-py312hecd8cb5_0\n",
      "appears to be corrupted. The path 'lib/python3.12/site-packages/conda/shell/etc/fish/conf.d/conda.fish'\n",
      "specified in the package manifest cannot be found.\n",
      "\n",
      "CondaVerificationError: The package for conda located at /opt/anaconda3/pkgs/conda-24.7.1-py312hecd8cb5_0\n",
      "appears to be corrupted. The path 'lib/python3.12/site-packages/conda/shell/etc/profile.d/conda.csh'\n",
      "specified in the package manifest cannot be found.\n",
      "\n",
      "CondaVerificationError: The package for conda located at /opt/anaconda3/pkgs/conda-24.7.1-py312hecd8cb5_0\n",
      "appears to be corrupted. The path 'lib/python3.12/site-packages/conda/shell/etc/profile.d/conda.sh'\n",
      "specified in the package manifest cannot be found.\n",
      "\n",
      "CondaVerificationError: The package for conda located at /opt/anaconda3/pkgs/conda-24.7.1-py312hecd8cb5_0\n",
      "appears to be corrupted. The path 'lib/python3.12/site-packages/conda/testing/__init__.py'\n",
      "specified in the package manifest cannot be found.\n",
      "\n",
      "CondaVerificationError: The package for conda located at /opt/anaconda3/pkgs/conda-24.7.1-py312hecd8cb5_0\n",
      "appears to be corrupted. The path 'lib/python3.12/site-packages/conda/testing/__pycache__/__init__.cpython-312.pyc'\n",
      "specified in the package manifest cannot be found.\n",
      "\n",
      "CondaVerificationError: The package for conda located at /opt/anaconda3/pkgs/conda-24.7.1-py312hecd8cb5_0\n",
      "appears to be corrupted. The path 'lib/python3.12/site-packages/conda/testing/__pycache__/fixtures.cpython-312.pyc'\n",
      "specified in the package manifest cannot be found.\n",
      "\n",
      "CondaVerificationError: The package for conda located at /opt/anaconda3/pkgs/conda-24.7.1-py312hecd8cb5_0\n",
      "appears to be corrupted. The path 'lib/python3.12/site-packages/conda/testing/__pycache__/helpers.cpython-312.pyc'\n",
      "specified in the package manifest cannot be found.\n",
      "\n",
      "CondaVerificationError: The package for conda located at /opt/anaconda3/pkgs/conda-24.7.1-py312hecd8cb5_0\n",
      "appears to be corrupted. The path 'lib/python3.12/site-packages/conda/testing/__pycache__/integration.cpython-312.pyc'\n",
      "specified in the package manifest cannot be found.\n",
      "\n",
      "CondaVerificationError: The package for conda located at /opt/anaconda3/pkgs/conda-24.7.1-py312hecd8cb5_0\n",
      "appears to be corrupted. The path 'lib/python3.12/site-packages/conda/testing/__pycache__/solver_helpers.cpython-312.pyc'\n",
      "specified in the package manifest cannot be found.\n",
      "\n",
      "CondaVerificationError: The package for conda located at /opt/anaconda3/pkgs/conda-24.7.1-py312hecd8cb5_0\n",
      "appears to be corrupted. The path 'lib/python3.12/site-packages/conda/testing/cases.py'\n",
      "specified in the package manifest cannot be found.\n",
      "\n",
      "CondaVerificationError: The package for conda located at /opt/anaconda3/pkgs/conda-24.7.1-py312hecd8cb5_0\n",
      "appears to be corrupted. The path 'lib/python3.12/site-packages/conda/testing/fixtures.py'\n",
      "specified in the package manifest cannot be found.\n",
      "\n",
      "CondaVerificationError: The package for conda located at /opt/anaconda3/pkgs/conda-24.7.1-py312hecd8cb5_0\n",
      "appears to be corrupted. The path 'lib/python3.12/site-packages/conda/testing/gateways/__init__.py'\n",
      "specified in the package manifest cannot be found.\n",
      "\n",
      "CondaVerificationError: The package for conda located at /opt/anaconda3/pkgs/conda-24.7.1-py312hecd8cb5_0\n",
      "appears to be corrupted. The path 'lib/python3.12/site-packages/conda/testing/gateways/__pycache__/fixtures.cpython-312.pyc'\n",
      "specified in the package manifest cannot be found.\n",
      "\n",
      "CondaVerificationError: The package for conda located at /opt/anaconda3/pkgs/conda-24.7.1-py312hecd8cb5_0\n",
      "appears to be corrupted. The path 'lib/python3.12/site-packages/conda/testing/gateways/fixtures.py'\n",
      "specified in the package manifest cannot be found.\n",
      "\n",
      "CondaVerificationError: The package for conda located at /opt/anaconda3/pkgs/conda-24.7.1-py312hecd8cb5_0\n",
      "appears to be corrupted. The path 'lib/python3.12/site-packages/conda/testing/helpers.py'\n",
      "specified in the package manifest cannot be found.\n",
      "\n",
      "CondaVerificationError: The package for conda located at /opt/anaconda3/pkgs/conda-24.7.1-py312hecd8cb5_0\n",
      "appears to be corrupted. The path 'lib/python3.12/site-packages/conda/testing/integration.py'\n",
      "specified in the package manifest cannot be found.\n",
      "\n",
      "CondaVerificationError: The package for conda located at /opt/anaconda3/pkgs/conda-24.7.1-py312hecd8cb5_0\n",
      "appears to be corrupted. The path 'lib/python3.12/site-packages/conda/testing/notices/__init__.py'\n",
      "specified in the package manifest cannot be found.\n",
      "\n",
      "CondaVerificationError: The package for conda located at /opt/anaconda3/pkgs/conda-24.7.1-py312hecd8cb5_0\n",
      "appears to be corrupted. The path 'lib/python3.12/site-packages/conda/testing/notices/__pycache__/helpers.cpython-312.pyc'\n",
      "specified in the package manifest cannot be found.\n",
      "\n",
      "CondaVerificationError: The package for conda located at /opt/anaconda3/pkgs/conda-24.7.1-py312hecd8cb5_0\n",
      "appears to be corrupted. The path 'lib/python3.12/site-packages/conda/testing/notices/fixtures.py'\n",
      "specified in the package manifest cannot be found.\n",
      "\n",
      "CondaVerificationError: The package for conda located at /opt/anaconda3/pkgs/conda-24.7.1-py312hecd8cb5_0\n",
      "appears to be corrupted. The path 'lib/python3.12/site-packages/conda/testing/notices/helpers.py'\n",
      "specified in the package manifest cannot be found.\n",
      "\n",
      "CondaVerificationError: The package for conda located at /opt/anaconda3/pkgs/conda-24.7.1-py312hecd8cb5_0\n",
      "appears to be corrupted. The path 'lib/python3.12/site-packages/conda/testing/solver_helpers.py'\n",
      "specified in the package manifest cannot be found.\n",
      "\n",
      "CondaVerificationError: The package for conda located at /opt/anaconda3/pkgs/conda-24.7.1-py312hecd8cb5_0\n",
      "appears to be corrupted. The path 'lib/python3.12/site-packages/conda/trust/__init__.py'\n",
      "specified in the package manifest cannot be found.\n",
      "\n",
      "CondaVerificationError: The package for conda located at /opt/anaconda3/pkgs/conda-24.7.1-py312hecd8cb5_0\n",
      "appears to be corrupted. The path 'lib/python3.12/site-packages/conda/trust/__pycache__/signature_verification.cpython-312.pyc'\n",
      "specified in the package manifest cannot be found.\n",
      "\n",
      "CondaVerificationError: The package for conda located at /opt/anaconda3/pkgs/conda-24.7.1-py312hecd8cb5_0\n",
      "appears to be corrupted. The path 'lib/python3.12/site-packages/conda/trust/constants.py'\n",
      "specified in the package manifest cannot be found.\n",
      "\n",
      "CondaVerificationError: The package for conda located at /opt/anaconda3/pkgs/conda-24.7.1-py312hecd8cb5_0\n",
      "appears to be corrupted. The path 'lib/python3.12/site-packages/conda/trust/signature_verification.py'\n",
      "specified in the package manifest cannot be found.\n",
      "\n",
      "CondaVerificationError: The package for conda located at /opt/anaconda3/pkgs/conda-24.7.1-py312hecd8cb5_0\n",
      "appears to be corrupted. The path 'lib/python3.12/site-packages/conda/utils.py'\n",
      "specified in the package manifest cannot be found.\n",
      "\n",
      "CondaVerificationError: The package for conda located at /opt/anaconda3/pkgs/conda-24.7.1-py312hecd8cb5_0\n",
      "appears to be corrupted. The path 'lib/python3.12/site-packages/conda_env/README.md'\n",
      "specified in the package manifest cannot be found.\n",
      "\n",
      "CondaVerificationError: The package for conda located at /opt/anaconda3/pkgs/conda-24.7.1-py312hecd8cb5_0\n",
      "appears to be corrupted. The path 'lib/python3.12/site-packages/conda_env/__init__.py'\n",
      "specified in the package manifest cannot be found.\n",
      "\n",
      "CondaVerificationError: The package for conda located at /opt/anaconda3/pkgs/conda-24.7.1-py312hecd8cb5_0\n",
      "appears to be corrupted. The path 'lib/python3.12/site-packages/conda_env/cli/__init__.py'\n",
      "specified in the package manifest cannot be found.\n",
      "\n",
      "CondaVerificationError: The package for conda located at /opt/anaconda3/pkgs/conda-24.7.1-py312hecd8cb5_0\n",
      "appears to be corrupted. The path 'lib/python3.12/site-packages/conda_env/cli/common.py'\n",
      "specified in the package manifest cannot be found.\n",
      "\n",
      "CondaVerificationError: The package for conda located at /opt/anaconda3/pkgs/conda-24.7.1-py312hecd8cb5_0\n",
      "appears to be corrupted. The path 'lib/python3.12/site-packages/conda_env/cli/main.py'\n",
      "specified in the package manifest cannot be found.\n",
      "\n",
      "CondaVerificationError: The package for conda located at /opt/anaconda3/pkgs/conda-24.7.1-py312hecd8cb5_0\n",
      "appears to be corrupted. The path 'lib/python3.12/site-packages/conda_env/cli/main_config.py'\n",
      "specified in the package manifest cannot be found.\n",
      "\n",
      "CondaVerificationError: The package for conda located at /opt/anaconda3/pkgs/conda-24.7.1-py312hecd8cb5_0\n",
      "appears to be corrupted. The path 'lib/python3.12/site-packages/conda_env/cli/main_create.py'\n",
      "specified in the package manifest cannot be found.\n",
      "\n",
      "CondaVerificationError: The package for conda located at /opt/anaconda3/pkgs/conda-24.7.1-py312hecd8cb5_0\n",
      "appears to be corrupted. The path 'lib/python3.12/site-packages/conda_env/cli/main_export.py'\n",
      "specified in the package manifest cannot be found.\n",
      "\n",
      "CondaVerificationError: The package for conda located at /opt/anaconda3/pkgs/conda-24.7.1-py312hecd8cb5_0\n",
      "appears to be corrupted. The path 'lib/python3.12/site-packages/conda_env/cli/main_list.py'\n",
      "specified in the package manifest cannot be found.\n",
      "\n",
      "CondaVerificationError: The package for conda located at /opt/anaconda3/pkgs/conda-24.7.1-py312hecd8cb5_0\n",
      "appears to be corrupted. The path 'lib/python3.12/site-packages/conda_env/cli/main_remove.py'\n",
      "specified in the package manifest cannot be found.\n",
      "\n",
      "CondaVerificationError: The package for conda located at /opt/anaconda3/pkgs/conda-24.7.1-py312hecd8cb5_0\n",
      "appears to be corrupted. The path 'lib/python3.12/site-packages/conda_env/cli/main_update.py'\n",
      "specified in the package manifest cannot be found.\n",
      "\n",
      "CondaVerificationError: The package for conda located at /opt/anaconda3/pkgs/conda-24.7.1-py312hecd8cb5_0\n",
      "appears to be corrupted. The path 'lib/python3.12/site-packages/conda_env/cli/main_vars.py'\n",
      "specified in the package manifest cannot be found.\n",
      "\n",
      "CondaVerificationError: The package for conda located at /opt/anaconda3/pkgs/conda-24.7.1-py312hecd8cb5_0\n",
      "appears to be corrupted. The path 'lib/python3.12/site-packages/conda_env/env.py'\n",
      "specified in the package manifest cannot be found.\n",
      "\n",
      "CondaVerificationError: The package for conda located at /opt/anaconda3/pkgs/conda-24.7.1-py312hecd8cb5_0\n",
      "appears to be corrupted. The path 'lib/python3.12/site-packages/conda_env/installers/__init__.py'\n",
      "specified in the package manifest cannot be found.\n",
      "\n",
      "CondaVerificationError: The package for conda located at /opt/anaconda3/pkgs/conda-24.7.1-py312hecd8cb5_0\n",
      "appears to be corrupted. The path 'lib/python3.12/site-packages/conda_env/installers/base.py'\n",
      "specified in the package manifest cannot be found.\n",
      "\n",
      "CondaVerificationError: The package for conda located at /opt/anaconda3/pkgs/conda-24.7.1-py312hecd8cb5_0\n",
      "appears to be corrupted. The path 'lib/python3.12/site-packages/conda_env/installers/conda.py'\n",
      "specified in the package manifest cannot be found.\n",
      "\n",
      "CondaVerificationError: The package for conda located at /opt/anaconda3/pkgs/conda-24.7.1-py312hecd8cb5_0\n",
      "appears to be corrupted. The path 'lib/python3.12/site-packages/conda_env/installers/pip.py'\n",
      "specified in the package manifest cannot be found.\n",
      "\n",
      "CondaVerificationError: The package for conda located at /opt/anaconda3/pkgs/conda-24.7.1-py312hecd8cb5_0\n",
      "appears to be corrupted. The path 'lib/python3.12/site-packages/conda_env/pip_util.py'\n",
      "specified in the package manifest cannot be found.\n",
      "\n",
      "CondaVerificationError: The package for conda located at /opt/anaconda3/pkgs/conda-24.7.1-py312hecd8cb5_0\n",
      "appears to be corrupted. The path 'lib/python3.12/site-packages/conda_env/specs/__init__.py'\n",
      "specified in the package manifest cannot be found.\n",
      "\n",
      "CondaVerificationError: The package for conda located at /opt/anaconda3/pkgs/conda-24.7.1-py312hecd8cb5_0\n",
      "appears to be corrupted. The path 'lib/python3.12/site-packages/conda_env/specs/binstar.py'\n",
      "specified in the package manifest cannot be found.\n",
      "\n",
      "CondaVerificationError: The package for conda located at /opt/anaconda3/pkgs/conda-24.7.1-py312hecd8cb5_0\n",
      "appears to be corrupted. The path 'lib/python3.12/site-packages/conda_env/specs/requirements.py'\n",
      "specified in the package manifest cannot be found.\n",
      "\n",
      "CondaVerificationError: The package for conda located at /opt/anaconda3/pkgs/conda-24.7.1-py312hecd8cb5_0\n",
      "appears to be corrupted. The path 'lib/python3.12/site-packages/conda_env/specs/yaml_file.py'\n",
      "specified in the package manifest cannot be found.\n",
      "\n",
      "CondaVerificationError: The package for conda located at /opt/anaconda3/pkgs/conda-24.7.1-py312hecd8cb5_0\n",
      "appears to be corrupted. The path 'lib/python3.12/site-packages/tests/test-recipes/activate_deactivate_package/src/etc/conda/activate.d/activate.bat'\n",
      "specified in the package manifest cannot be found.\n",
      "\n",
      "CondaVerificationError: The package for conda located at /opt/anaconda3/pkgs/conda-24.7.1-py312hecd8cb5_0\n",
      "appears to be corrupted. The path 'lib/python3.12/site-packages/tests/test-recipes/activate_deactivate_package/src/etc/conda/activate.d/activate.sh'\n",
      "specified in the package manifest cannot be found.\n",
      "\n",
      "CondaVerificationError: The package for conda located at /opt/anaconda3/pkgs/conda-24.7.1-py312hecd8cb5_0\n",
      "appears to be corrupted. The path 'lib/python3.12/site-packages/tests/test-recipes/activate_deactivate_package/src/etc/conda/deactivate.d/deactivate.bat'\n",
      "specified in the package manifest cannot be found.\n",
      "\n",
      "CondaVerificationError: The package for conda located at /opt/anaconda3/pkgs/conda-24.7.1-py312hecd8cb5_0\n",
      "appears to be corrupted. The path 'lib/python3.12/site-packages/tests/test-recipes/activate_deactivate_package/src/etc/conda/deactivate.d/deactivate.sh'\n",
      "specified in the package manifest cannot be found.\n",
      "\n",
      "CondaVerificationError: The package for conda located at /opt/anaconda3/pkgs/conda-24.7.1-py312hecd8cb5_0\n",
      "appears to be corrupted. The path 'lib/python3.12/site-packages/xontrib/conda.xsh'\n",
      "specified in the package manifest cannot be found.\n",
      "\n",
      "CondaVerificationError: The package for conda located at /opt/anaconda3/pkgs/conda-24.7.1-py312hecd8cb5_0\n",
      "appears to be corrupted. The path 'shell/condabin/Conda.psm1'\n",
      "specified in the package manifest cannot be found.\n",
      "\n",
      "CondaVerificationError: The package for conda located at /opt/anaconda3/pkgs/conda-24.7.1-py312hecd8cb5_0\n",
      "appears to be corrupted. The path 'shell/condabin/conda-hook.ps1'\n",
      "specified in the package manifest cannot be found.\n",
      "\n",
      "\n"
     ]
    }
   ],
   "source": [
    "!conda install -y inflect"
   ]
  },
  {
   "cell_type": "code",
   "execution_count": 1,
   "id": "c68c5514-6732-46c2-a853-d3cf42a3b0d4",
   "metadata": {},
   "outputs": [
    {
     "name": "stdout",
     "output_type": "stream",
     "text": [
      "Collecting inflect\n",
      "  Downloading inflect-7.4.0-py3-none-any.whl.metadata (21 kB)\n",
      "Requirement already satisfied: more-itertools>=8.5.0 in /opt/anaconda3/lib/python3.12/site-packages (from inflect) (10.1.0)\n",
      "Collecting typeguard>=4.0.1 (from inflect)\n",
      "  Downloading typeguard-4.3.0-py3-none-any.whl.metadata (3.7 kB)\n",
      "Requirement already satisfied: typing-extensions>=4.10.0 in /opt/anaconda3/lib/python3.12/site-packages (from typeguard>=4.0.1->inflect) (4.11.0)\n",
      "Downloading inflect-7.4.0-py3-none-any.whl (34 kB)\n",
      "Downloading typeguard-4.3.0-py3-none-any.whl (35 kB)\n",
      "Installing collected packages: typeguard, inflect\n",
      "Successfully installed inflect-7.4.0 typeguard-4.3.0\n",
      "Note: you may need to restart the kernel to use updated packages.\n"
     ]
    }
   ],
   "source": [
    "pip install inflect"
   ]
  },
  {
   "cell_type": "code",
   "execution_count": 25,
   "id": "56ec3ef1-b31e-4f60-b70d-7acbc7d7eb9e",
   "metadata": {},
   "outputs": [
    {
     "name": "stdout",
     "output_type": "stream",
     "text": [
      "1\n",
      "1\t1\n",
      "1\t2\t1\n",
      "1\t3\t3\t1\n",
      "1\t4\t6\t4\t1\n",
      "1\t5\t10\t10\t5\t1\n",
      "1\t6\t15\t20\t15\t6\t1\n",
      "1\t7\t21\t35\t35\t21\t7\t1\n"
     ]
    }
   ],
   "source": [
    "# Function to generate Pascal's Triangle up to n rows\n",
    "def generate_pascals_triangle(n):\n",
    "    triangle = []  # List to hold all rows of Pascal's Triangle\n",
    "    \n",
    "    for i in range(n):\n",
    "        row = [1]  # Every row starts with 1\n",
    "        if i > 0:\n",
    "            for j in range(1, i):  # Calculate the intermediate values of the row\n",
    "                # Add the two values from the previous row to get the current value\n",
    "                row.append(triangle[i-1][j-1] + triangle[i-1][j])\n",
    "            row.append(1)  # Every row ends with 1\n",
    "        triangle.append(row)  # Add the row to the triangle\n",
    "    \n",
    "    return triangle\n",
    "\n",
    "# Function to print Pascal's Triangle with tab-separated values\n",
    "def print_pascals_triangle(triangle):\n",
    "    for row in triangle:\n",
    "        print(\"\\t\".join(map(str, row)))  # Convert each row to string and join with tabs\n",
    "\n",
    "# Generate the first 8 rows of Pascal's Triangle\n",
    "rows = 8\n",
    "pascals_triangle = generate_pascals_triangle(rows)\n",
    "\n",
    "# Print Pascal's Triangle\n",
    "print_pascals_triangle(pascals_triangle)\n"
   ]
  },
  {
   "cell_type": "code",
   "execution_count": 1,
   "id": "040d0d08-8e03-4576-addf-73c1bd33e39b",
   "metadata": {},
   "outputs": [
    {
     "name": "stdout",
     "output_type": "stream",
     "text": [
      "Generated Password: _L]y#6,]\\)DW\n"
     ]
    }
   ],
   "source": [
    "import random\n",
    "\n",
    "def generate_password(length):\n",
    "    # Ensure that the length is valid\n",
    "    if length <= 0:\n",
    "        return \"Invalid length. Please enter a positive number.\"\n",
    "\n",
    "    password = \"\"\n",
    "    for _ in range(length):\n",
    "        # Generate a random number between 33 and 126 (inclusive)\n",
    "        random_decimal = random.randint(33, 126)\n",
    "        # Convert the random number to the corresponding ASCII character\n",
    "        password += chr(random_decimal)\n",
    "    \n",
    "    return password\n",
    "\n",
    "# Example: Generate a password of length 12\n",
    "password_length = 12\n",
    "password = generate_password(password_length)\n",
    "print(\"Generated Password:\", password)"
   ]
  },
  {
   "cell_type": "code",
   "execution_count": null,
   "id": "9b79505b-0b64-4e8c-9ae8-aa5a8f46c1ba",
   "metadata": {},
   "outputs": [],
   "source": []
  }
 ],
 "metadata": {
  "kernelspec": {
   "display_name": "Python 3 (ipykernel)",
   "language": "python",
   "name": "python3"
  },
  "language_info": {
   "codemirror_mode": {
    "name": "ipython",
    "version": 3
   },
   "file_extension": ".py",
   "mimetype": "text/x-python",
   "name": "python",
   "nbconvert_exporter": "python",
   "pygments_lexer": "ipython3",
   "version": "3.12.4"
  }
 },
 "nbformat": 4,
 "nbformat_minor": 5
}
